Workbook

Sheet Biodata
A2: Citi-Nati Supermarket
A4: Employee List
A6: Pay Incremental Factor (based on Unitterupted Service
A7: 1 to 6 months in service | C7: 0
A8: 6 months to 1 year in service | C8: 0
A9: 1 year to 5 years in service | C9: 0
A10: 5 years and above in service | C10: 0
A12: Management Team
A14: Emp No. | B14: First Name | C14: Surname | D14: Agreed Salary per Month | E14: Annual Increment | F14: Salary after Increment | G14: Date of Birth | H14: District of Origin | I14: Village | J14: Traditional Authority | K14: National Identification Card | L14: Expiry Date | M14: Date of Employment | N14: Contact Number | P14: 1 | Q14: Daniel Mponda | S14: 60000
A15: CITI01 | B15: Sapulene | C15: Mkulichi | D15: 0 | E15: =IF(Wages!R162="vacant",0,IF(Wages!R162/30<6,0,IF(Wages!R162/30<12,D15*$C$8/100,IF(Wages!R162/30<60,D15*$C$9/100,IF(Wages!R162/30>59,D15*$C$10/100,""))))) -> 0 | F15: =IF(B15="vacant",0,D15+E15) -> 0 | G15: 24438 | H15: Zomba | I15: Chikwekwe | J15: Mulumbe | K15: K7Q3TYCY | L15: 44892 | M15: 35799 | N15: 0999953442 | P15: =+P14+1 -> 2 | Q15: Martin Kandalama | S15: 70000
A16: CITI02 | B16: George | C16: Matemba | D16: 120000 | E16: =IF(Wages!R163="vacant",0,IF(Wages!R163/30<6,0,IF(Wages!R163/30<12,D16*$C$8/100,IF(Wages!R163/30<60,D16*$C$9/100,IF(Wages!R163/30>59,D16*$C$10/100,""))))) -> 0 | F16: =IF(B16="vacant",0,D16+E16) -> 120000 | G16: 32946 | H16: Zomba | I16: Chikwekwe | J16: Mulumbe | K16: SX5E2R90 | L16: 45730 | M16: 41630 | N16: 0888109501 | P16: =+P15+1 -> 3 | Q16: Elizabeth Kabudula | S16: 30000
A17: CITI03 | B17: vacant | D17: 100000 | E17: =IF(Wages!R164="vacant",0,IF(Wages!R164/30<6,0,IF(Wages!R164/30<12,D17*$C$8/100,IF(Wages!R164/30<60,D17*$C$9/100,IF(Wages!R164/30>59,D17*$C$10/100,""))))) -> 0 | F17: =IF(B17="vacant",0,D17+E17) -> 0 | G17: 27/06/2000 | H17: Blantyre | I17: Kunjawa | J17: Kapeni | K17: 00JPEBYO | L17: 27/06/2026 | M17: 45386 | N17: 0995261886 | P17: =+P16+1 -> 4 | Q17: Henry Saona | S17: 150000
P18: =+P17+1 -> 5 | Q18: James Bongwe | S18: 100000
A19: Domasi Supermarket Employees | P19: =+P18+1 -> 6 | Q19: Yankho Gulani | S19: 100000
Q20: Sub-Total | S20: =SUM(S14:S19) -> 510000
A21: Emp No. | B21: First Name | C21: Surname | D21: Agreed Salary per Month | E21: Annual Increment | F21: Salary after Increment | G21: Date of Birth | H21: District of Origin | I21: Village | J21: Traditional Authority | K21: National Identification Card | L21: Expiry Date | M21: Date of Employment | N21: =N14 -> Contact Number
A22: CITI04 | B22: Alinafe | C22: James | D22: 80000 | E22: =IF(Wages!R165="vacant",0,IF(Wages!R165/30<6,0,IF(Wages!R165/30<12,D22*$C$8/100,IF(Wages!R165/30<60,D22*$C$9/100,IF(Wages!R165/30>59,D22*$C$10/100,""))))) -> 0 | F22: =IF(B22="vacant",0,D22+E22) -> 80000 | G22: 44139 | H22: Zomba | I22: Malonje | J22: Malemia | K22: TS62TH8A | L22: 20/10/2032 | M22: 44854 | N22: 0888529172/0995826404 | Q22: Citi-Nati Supermarkets, Resturant and Stop Over
A23: CITI05 | B23: Chimwemwe | C23: Banda | D23: 80000 | E23: =IF(Wages!R166="vacant",0,IF(Wages!R166/30<6,0,IF(Wages!R166/30<12,D23*$C$8/100,IF(Wages!R166/30<60,D23*$C$9/100,IF(Wages!R166/30>59,D23*$C$10/100,""))))) -> 0 | F23: =IF(B23="vacant",0,D23+E23) -> 80000 | G23: 22/04/1998 | H23: Blantyre | I23: Puna | J23: Machinjiri | M23: 45204 | P23: 1 | Q23: George Matemba | S23: 140000
A24: CITI06 | B24: vacant | D24: 0 | E24: =IF(Wages!R167="vacant",0,IF(Wages!R167/30<6,0,IF(Wages!R167/30<12,D24*$C$8/100,IF(Wages!R167/30<60,D24*$C$9/100,IF(Wages!R167/30>59,D24*$C$10/100,""))))) -> 0 | F24: =IF(B24="vacant",0,D24+E24) -> 0 | G24: 31/07/2000 | H24: Ntcheu | I24: Jenya | J24: Mphambala | K24: OONSKXV4 | L24: 31/07/2026 | M24: 45488 | N24: 0991231359 | P24: =P23+1 -> 2 | Q24: Alinafe James | S24: 0
A25: CITI07 | B25: Maureen | C25: Ulaya | D25: =+S38 -> 80000 | E25: =IF(Wages!R159="vacant",0,IF(Wages!R159/30<6,0,IF(Wages!R159/30<12,D25*$C$8/100,IF(Wages!R159/30<60,D25*$C$9/100,IF(Wages!R159/30>59,D25*$C$10/100,""))))) -> 0 | F25: =IF(B25="vacant",0,D25+E25) -> 80000 | M25: 45809 | N25: 0995337862 | P25: =P24+1 -> 3 | Q25: Francis Nebert | S25: 0
A26: CITI08 | B26: Francis | C26: Chatsweka | D26: 70000 | E26: =IF(Wages!R169="vacant",0,IF(Wages!R169/30<6,0,IF(Wages!R169/30<12,D26*$C$8/100,IF(Wages!R169/30<60,D26*$C$9/100,IF(Wages!R169/30>59,D26*$C$10/100,""))))) -> 0 | F26: =IF(B26="vacant",0,D26+E26) -> 70000 | G26: 32972 | H26: Zomba | I26: Yoyola | J26: Malemia | K26: T711G2DS | L26: 46121 | M26: 45241 | P26: =P25+1 -> 4 | Q26: Chimwemwe Banda | S26: 70000
A27: CITI09 | B27: Stenala | C27: Mponda | D27: 70000 | E27: =IF(Wages!R170="vacant",0,IF(Wages!R170/30<6,0,IF(Wages!R170/30<12,D27*$C$8/100,IF(Wages!R170/30<60,D27*$C$9/100,IF(Wages!R170/30>59,D27*$C$10/100,""))))) -> 0 | F27: =IF(B27="vacant",0,D27+E27) -> 70000 | G27: 26/04/1980 | H27: Machinga | I27: Mkwanda | J27: Ngokwe | K27: Q9EJ6EJD | L27: 26/04/2026 | M27: 45533 | N27: 0997793088 | P27: =P26+1 -> 5 | Q27: Francis Chatsweka | S27: 60000
A28: CITI10 | B28: Simikizani | C28: Siki | D28: 70000 | E28: =IF(Wages!R171="vacant",0,IF(Wages!R171/30<6,0,IF(Wages!R171/30<12,D28*$C$8/100,IF(Wages!R171/30<60,D28*$C$9/100,IF(Wages!R171/30>59,D28*$C$10/100,""))))) -> 0 | F28: =IF(B28="vacant",0,D28+E28) -> 70000 | M28: 45163 | P28: =P27+1 -> 6 | Q28: Stenala Mponda | S28: 60000
A29: CITI11 | B29: Amini | C29: Wecha | D29: 70000 | E29: =IF(Wages!R172="vacant",0,IF(Wages!R172/30<6,0,IF(Wages!R172/30<12,D29*$C$8/100,IF(Wages!R172/30<60,D29*$C$9/100,IF(Wages!R172/30>59,D29*$C$10/100,""))))) -> 0 | F29: =IF(B29="vacant",0,D29+E29) -> 70000 | M29: 45838 | P29: =P28+1 -> 7 | Q29: Simikizani Siki | S29: 60000
P30: =P29+1 -> 8 | Q30: Tayifolo Mandowa | S30: 120000
P31: =P30+1 -> 9 | Q31: Monica George | S31: 80000
A32: Stop Over Employees | P32: =P31+1 -> 10 | Q32: Madalitso Baluti | S32: 90000
P33: =P32+1 -> 11 | Q33: Peter James | S33: 60000
A34: Emp No. | B34: First Name | C34: Surname | D34: Agreed Salary per Month | E34: Annual Increment | F34: Salary after Increment | G34: Date of Birth | H34: District of Origin | I34: Village | J34: Traditional Authority | K34: National Identification Card | L34: Expiry Date | M34: Date of Employment | N34: =N21 -> Contact Number | P34: =P33+1 -> 12 | Q34: Maggie Billy | S34: 60000
A35: CITI12 | B35: Tayifolo | C35: Mandowa | D35: =+S30 -> 120000 | E35: =IF(Wages!R173="vacant",0,IF(Wages!R173/30<6,0,IF(Wages!R173/30<12,D35*$C$8/100,IF(Wages!R173/30<60,D35*$C$9/100,IF(Wages!R173/30>59,D35*$C$10/100,""))))) -> 0 | F35: =IF(B35="vacant",0,D35+E35) -> 120000 | G35: 26/04/1980 | H35: Machinga | I35: Mkwanda | J35: Ngokwe | K35: Q9EJ6EJD | L35: 26/04/2026 | M35: 45533 | N35: 0997793088 | P35: =P34+1 -> 13 | Q35: Amini Wecha | S35: 60000
A36: CITI13 | B36: Monica | C36: George | D36: =+S31 -> 80000 | E36: =IF(Wages!R174="vacant",0,IF(Wages!R174/30<6,0,IF(Wages!R174/30<12,D36*$C$8/100,IF(Wages!R174/30<60,D36*$C$9/100,IF(Wages!R174/30>59,D36*$C$10/100,""))))) -> 0 | F36: =IF(B36="vacant",0,D36+E36) -> 80000 | G36: 16/04/1997 | H36: Machinga | I36: Kagwa | J36: Liwonde | M36: 45385 | N36: 0882689123 | P36: =P35+1 -> 14 | Q36: Agness Mponda | S36: =Biodata!S70 -> 0
A37: CITI14 | B37: Madalitso | C37: Baluti | D37: =+S32 -> 90000 | E37: =IF(Wages!R175="vacant",0,IF(Wages!R175/30<6,0,IF(Wages!R175/30<12,D37*$C$8/100,IF(Wages!R175/30<60,D37*$C$9/100,IF(Wages!R175/30>59,D37*$C$10/100,""))))) -> 0 | F37: =IF(B37="vacant",0,D37+E37) -> 90000 | G37: 16/03/1998 | H37: Zomba | I37: Makuwira | J37: Makuwira | M37: 45663 | P37: =P36+1 -> 15 | Q37: Elizabeth Chinkono | S37: 100000
P38: =P37+1 -> 16 | Q38: Maureen Ulaya | S38: 80000
P39: =P38+1 -> 17 | Q39: Leonard Stephano | S39: =Biodata!S72 -> 0
A40: Restaurant Employees | P40: =P39+1 -> 18 | Q40: Ibrahim Amadu | S40: 80000
A42: Emp No. | B42: First Name | C42: Surname | D42: Agreed Salary per Month | E42: Annual Increment | F42: Salary after Increment | G42: Date of Birth | H42: District of Origin | I42: Village | J42: Traditional Authority | K42: National Identification Card | L42: Expiry Date | M42: Date of Employment | N42: =N34 -> Contact Number
A43: CITI15 | B43: Peter | C43: James | D43: =+S33 -> 60000 | E43: =IF(Wages!R176="vacant",0,IF(Wages!R176/30<6,0,IF(Wages!R176/30<12,D43*$C$8/100,IF(Wages!R176/30<60,D43*$C$9/100,IF(Wages!R176/30>59,D43*$C$10/100,""))))) -> 0 | F43: =IF(B43="vacant",0,D43+E43) -> 60000 | G43: 16/03/2000 | H43: Zomba | I43: Saidi | J43: Mwambo | M43: 45558
A44: CITI16 | B44: Maggie | C44: Billy | D44: 80000 | E44: =IF(Wages!R177="vacant",0,IF(Wages!R177/30<6,0,IF(Wages!R177/30<12,D44*$C$8/100,IF(Wages!R177/30<60,D44*$C$9/100,IF(Wages!R177/30>59,D44*$C$10/100,""))))) -> 0 | F44: =IF(B44="vacant",0,D44+E44) -> 80000 | G44: 17/06/2000 | H44: Zomba | I44: Sani | J44: Chikowi | M44: 45421
A45: CITI17 | B45: vacant | E45: =IF(Wages!R178="vacant",0,IF(Wages!R178/30<6,0,IF(Wages!R178/30<12,D45*$C$8/100,IF(Wages!R178/30<60,D45*$C$9/100,IF(Wages!R178/30>59,D45*$C$10/100,""))))) -> 0 | F45: =IF(B45="vacant",0,D45+E45) -> 0 | M45: 43665
A46: CITI18 | B46: Esnat | C46: Adam | D46: 80000 | E46: =IF(Wages!R179="vacant",0,IF(Wages!R179/30<6,0,IF(Wages!R179/30<12,D46*$C$8/100,IF(Wages!R179/30<60,D46*$C$9/100,IF(Wages!R179/30>59,D46*$C$10/100,""))))) -> 0 | F46: =IF(B46="vacant",0,D46+E46) -> 80000 | G46: 36157 | H46: Zomba | I46: Potani | J46: Mlumbe | K46: WHTVMCR | L46: 12781 | M46: 45901 | N46: 09
...

Sheet Pay Sheet
A1: Citi-Nati Supermarket
B2: Enter Month to Pay Here--------------> | C2: 1
B3: Enter Position in Month to pay Here | C3: 1 | D3: (Enter 1 for mid, 2 for full month)
A5: Wages for Residences, Supermarket, Stop-Over and Restaurant
B7: ='Combined Pay'!B6 -> Month for Payment of Wages: | C7: ='Combined Pay'!C6 -> Mid | D7: ='Combined Pay'!D6 -> January 2026
A9: Total Wages Due | D9: =D21+D48 -> 967000
A11: Count | B11: Nyambadwe and Domasi Residence
A12: ='Combined Pay'!A13 -> 1 | B12: ='Combined Pay'!B13 -> Martin Kandalama | D12: ='Combined Pay'!D13 -> 35000
A13: =SUM(A12+1) -> 2 | B13: ='Combined Pay'!B14 -> Daniel Mponda | D13: ='Combined Pay'!D14 -> 35000
A14: =SUM(A13+1) -> 3 | B14: ='Combined Pay'!B15 -> Elizabeth Kabudula | D14: ='Combined Pay'!D15 -> 10000
A15: =A14+1 -> 4 | B15: ='Combined Pay'!B16 -> vacant | D15: ='Combined Pay'!D16 -> 0
A16: =A15+1 -> 5 | B16: ='Combined Pay'!B17 -> William Mahinya | D16: ='Combined Pay'!D17 -> 75000
A17: =A16+1 -> 6 | B17: ='Combined Pay'!B18 -> vacant | D17: ='Combined Pay'!D18 -> 0
A18: =A17+1 -> 7 | B18: ='Combined Pay'!B19 | D18: ='Combined Pay'!D19 -> 0
A19: =A18+1 -> 8 | B19: ='Combined Pay'!B20 -> vacant | D19: ='Combined Pay'!D20 -> 0
A20: =A19+1 -> 9 | B20: ='Combined Pay'!B21 -> Yankho Gulani | D20: ='Combined Pay'!D21 -> 60000
B21: ='Combined Pay'!B22 -> Sub-Total | D21: =SUM(D12:D20) -> 215000
A23: Count | B23: ='Combined Pay'!B24 -> Citi-Nati Supermarkets, Resturant and Stop Over
A24: 1 | B24: ='Combined Pay'!B25 -> Sapulene Mkulichi | D24: ='Combined Pay'!D25 -> 0
A25: =SUM(A24+1) -> 2 | B25: ='Combined Pay'!B26 -> George Matemba | D25: ='Combined Pay'!D26 -> 60000
A26: =SUM(A25+1) -> 3 | B26: ='Combined Pay'!B27 -> vacant | D26: ='Combined Pay'!D27 -> 0
A27: =SUM(A26+1) -> 4 | B27: ='Combined Pay'!B28 -> Alinafe James | D27: ='Combined Pay'!D28 -> 40000
A28: =SUM(A27+1) -> 5 | B28: ='Combined Pay'!B29 -> Chimwemwe Banda | D28: ='Combined Pay'!D29 -> 40000
A29: =SUM(A28+1) -> 6 | B29: ='Combined Pay'!B30 -> vacant | D29: ='Combined Pay'!D30 -> 0
A30: =SUM(A29+1) -> 7 | B30: ='Combined Pay'!B31 -> Maureen Ulaya | D30: ='Combined Pay'!D31 -> 40000
A31: =SUM(A30+1) -> 8 | B31: ='Combined Pay'!B32 -> Francis Chatsweka | D31: ='Combined Pay'!D32 -> 35000
A32: =SUM(A31+1) -> 9 | B32: ='Combined Pay'!B33 -> Stenala Mponda | D32: ='Combined Pay'!D33 -> 35000
A33: =SUM(A32+1) -> 10 | B33: ='Combined Pay'!B34 -> Simikizani Siki | D33: ='Combined Pay'!D34 -> 35000
A34: =SUM(A33+1) -> 11 | B34: ='Combined Pay'!B35 -> Amini Wecha | D34: ='Combined Pay'!D35 -> 35000
A35: =SUM(A34+1) -> 12 | B35: ='Combined Pay'!B36 -> Tayifolo Mandowa | D35: ='Combined Pay'!D36 -> 60000
A36: =SUM(A35+1) -> 13 | B36: ='Combined Pay'!B37 -> Monica George | D36: ='Combined Pay'!D37 -> 40000
... A46: =SUM(A45+1) -> 23 | B46: ='Combined Pay'!B47 -> Ibrahim Amadu | D46: ='Combined Pay'!D47 -> 40000
B48: ='Combined Pay'!B49 -> Sub-Total | D48: =SUM(D24:D46) -> 752000
D50: Amounts Due
B51: Management Employees | D51: =Wages!R257 -> 120000
B52: Domasi Supermarket Employees | D52: =Wages!R258 -> 520000
B53: Stop-Over Employees | D53: =Wages!R259 -> 290000
B54: Restuarant Employees | D54: =Wages!R260 -> 220000
B55: Domasi Residence Employees | D55: =Wages!R261 -> 160000
B56: Nyambadwe Residence Employees | D56: =Wages!R262 -> 270000
...

Sheet Final
A1: Citi-Nati Supermarket
A3: Wages for Residences, Supermarket, Stop-Over and Restaurant
B5: ='Combined Pay'!B6 -> Month for Payment of Wages: | C5: ='Combined Pay'!C6 -> Mid | D5: ='Combined Pay'!D6 -> January 2026
A7: Total Wages Due | D7: =D15+D36 -> 967000
A9: Count | B9: Nyambadwe and Domasi Residence
A10: 1 | B10: ='Pay Sheet'!B12 -> Martin Kandalama | D10: =+'Pay Sheet'!D12 -> 35000
A11: =SUM(A10+1) -> 2 | B11: ='Pay Sheet'!B13 -> Daniel Mponda | D11: =+'Pay Sheet'!D13 -> 35000
A12: =SUM(A11+1) -> 3 | B12: ='Pay Sheet'!B14 -> Elizabeth Kabudula | D12: =+'Pay Sheet'!D14 -> 10000
A13: =SUM(A12+1) -> 4 | B13: ='Pay Sheet'!B20 -> Yankho Gulani | D13: =+'Pay Sheet'!D20 -> 60000
A14: =SUM(A13+1) -> 5 | B14: ='Pay Sheet'!B16 -> William Mahinya | D14: ='Pay Sheet'!D16 -> 75000
B15: ='Pay Sheet'!B21 -> Sub-Total | D15: =SUM(D10:D14) -> 215000
B17: ='Pay Sheet'!B23 -> Citi-Nati Supermarkets, Resturant and Stop Over
A18: 1 | B18: ='Pay Sheet'!B25 -> George Matemba | D18: =+'Pay Sheet'!D25 -> 60000
A19: =+A18+1 -> 2 | B19: ='Pay Sheet'!B27 -> Alinafe James | D19: =+'Pay Sheet'!D27 -> 40000
A20: =+A19+1 -> 3 | B20: ='Pay Sheet'!B28 -> Chimwemwe Banda | D20: =+'Pay Sheet'!D28 -> 40000
A21: =+A20+1 -> 4 | B21: ='Pay Sheet'!B30 -> Maureen Ulaya | D21: =+'Pay Sheet'!D30 -> 40000
A22: =+A21+1 -> 5 | B22: ='Pay Sheet'!B31 -> Francis Chatsweka | D22: =+'Pay Sheet'!D31 -> 35000 | F22: =+'Pay Sheet'!D9-Final!D7 -> 0
A23: =+A22+1 -> 6 | B23: ='Pay Sheet'!B32 -> Stenala Mponda | D23: =+'Pay Sheet'!D32 -> 35000
A24: =+A23+1 -> 7 | B24: ='Pay Sheet'!B33 -> Simikizani Siki | D24: =+'Pay Sheet'!D33 -> 35000
A25: =+A24+1 -> 8 | B25: ='Pay Sheet'!B34 -> Amini Wecha | D25: =+'Pay Sheet'!D34 -> 35000
A26: =+A25+1 -> 9 | B26: ='Pay Sheet'!B35 -> Tayifolo Mandowa | D26: =+'Pay Sheet'!D35 -> 60000
A27: =+A26+1 -> 10 | B27: ='Pay Sheet'!B36 -> Monica George | D27: =+'Pay Sheet'!D36 -> 40000
A28: =+A27+1 -> 11 | B28: ='Pay Sheet'!B37 -> Madalitso Baluti | D28: =+'Pay Sheet'!D37 -> 45000
A29: =+A28+1 -> 12 | B29: ='Pay Sheet'!B38 -> Peter James | D29: =+'Pay Sheet'!D38 -> 30000
A30: =+A29+1 -> 13 | B30: ='Pay Sheet'!B39 -> Maggie Billy | D30: =+'Pay Sheet'!D39 -> 40000
A31: =+A30+1 -> 14 | B31: ='Pay Sheet'!B41 -> Esnat Adam | D31: =+'Pay Sheet'!D41 -> 40000
A32: =+A31+1 -> 15 | B32: ='Pay Sheet'!B42 -> Agness Mponda | D32: =+'Pay Sheet'!D42 -> 40000
A33: =+A32+1 -> 16 | B33: ='Pay Sheet'!B43 -> Elizabeth Chinkono | D33: =+'Pay Sheet'!D43 -> 50000
A34: =+A33+1 -> 17 | B34: ='Pay Sheet'!B45 -> Dancan Botha | D34: =+'Pay Sheet'!D45 -> 47000
A35: =+A34+1 -> 18 | B35: ='Pay Sheet'!B46 -> Ibrahim Amadu | D35: =+'Pay Sheet'!D46 -> 40000
B36: ='Pay Sheet'!B48 -> Sub-Total | D36: =SUM(D18:D35) -> 752000
D39: =+'Pay Sheet'!D50 -> Amounts Due
B40: =+'Pay Sheet'!B51 -> Management Employees | D40: =+'Pay Sheet'!D51 -> 120000
B41: =+'Pay Sheet'!B52 -> Domasi Supermarket Employees | D41: =+'Pay Sheet'!D52 -> 520000
B42: =+'Pay Sheet'!B53 -> Stop-Over Employees | D42: =+'Pay Sheet'!D53 -> 290000
B43: =+'Pay Sheet'!B54 -> Restuarant Employees | D43: =+'Pay Sheet'!D54 -> 220000
B44: =+'Pay Sheet'!B55 -> Domasi Residence Employees | D44: =+'Pay Sheet'!D55 -> 160000
B45: =+'Pay Sheet'!B56 -> Nyambadwe Residence Employees | D45: =+'Pay Sheet'!D56 -> 270000
B46: =+'Pay Sheet'!B57 -> Chinyonga Supermarket Employees | D46: =+'Pay Sheet'!D57 -> 354000
B47: =+'Pay Sheet'!B58 -> Total Wages to Pay Entire Month | D47: =+'Pay Sheet'!D58 -> 1934000

Sheet Terminations
A1: Citi-Nati Supermarket
A5: =Wages!K216 -> Termination of Contract Calculations
A6: Enter Employee to Terminate Contract | B6: james
A7: Enter Date of Termination | B7: 45626
A8: Enter Reason to Terminate Contract | B8: 2 | C8: (Enter 1 for termination or 2 for resignation)
A9: Enter Days Worked During the Month of Termination | B9: 0
A10: Did Employee Received Half Pay Wage? | B10: 0 | C10: (enter 1 if yes or 0 if no)
A11: Total amount due after Termination | B11: =Wages!G241 -> Not applicable
A12: Total Amount due after Resignation/Dismissal | B12: =Wages!G277 -> Nil
A14: =Wages!A216 -> Employer Induced Termination
A15: =Wages!A219 -> Name of Employee: | B15: =Wages!F219 -> Not Applicable
A17: =Wages!A221 -> Date Contract Terminated | B17: =Wages!G221 -> Not applicable
A18: =Wages!A223 -> Payslip for end of Contract | B18: =Wages!G223 -> Not applicable
A19: =Wages!A225 -> Number of Months Worked Continously | B19: =Wages!G225 -> Not applicable
A20: =Wages!A227 -> Gratuity at 5% of the last salary mutiplied by Number of Months of Uninterrupted Employment | B20: =Wages!G227 -> Not applicable
A21: =Wages!A229 -> Accrued Leave Days in Number of Months Worked Continuously | B21: =Wages!G229 -> Not applicable
A22: =Wages!A231 -> Leave Pay on Accrued Leave Days | B22: =Wages!G231 -> Not applicable
A23: =Wages!A233 -> One Month Pay In Lieu of Notice | B23: =Wages!G233 -> Not applicable
A24: =Wages!A235 -> Total Gross Amount Due at End of Contract | B24: =Wages!G235 -> Not applicable
A25: =Wages!A237 -> Less Outstanding Loan Obligations | B25: =Wages!G237 -> Not applicable
A26: =Wages!A239 -> Less part-payment of Salary made during mid month of | B26: =IF(B10=1,Wages!G239,"Not applicable") -> Not applicable
A27: =Wages!A241 -> Total Net Amount Due at End of Contract | B27: =Wages!G241 -> Not applicable
A28: =Wages!A243 -> Employer's Signature Confirming Payment of the Net Amount Due Following End of Contract | B28: ------------------------------------------
A29: =Wages!A245 -> Employee's Signature agreeing to the amount due following end of Contract | B29: ------------------------------------------
A30: =Wages!A247 -> Date signed | B30: ------------------------------------------
A33: =Wages!A252 -> Employee Resignation/Dismissal
A34: =Wages!A255 -> Name of Employee: | B34: =Wages!F255 -> Employee does not exist
A36: =Wages!A257 -> Date Contract Terminated | B36: =Wages!G257 -> None
A37: =Wages!A259 -> Payslip for end of Contract | B37: =Wages!G259 -> None
A38: =Wages!A261 -> Number of Months Worked Continously | B38: =Wages!G261 -> Nil
A39: =Wages!A263 -> Number of days worked during month of resignation/dismissal | B39: =Wages!G263 -> Nil
A40: =Wages!A265 -> Salary for days worked during month of resignation/dismissal | B40: =Wages!G265 -> Nil
A41: =Wages!A267 -> One Month Pay In Lieu of Notice | B41: =Wages!G267 -> Nil
A42: =Wages!A269 -> Gratuity at 5% of the last salary mutiplied by Number of Months of Uninterrupted Employment | B42: =Wages!G269 -> Nil
A43: =Wages!A271 -> Total Gross Amount Due at End of Contract | B43: =Wages!G271 -> Nil
A44: =Wages!A273 -> Less Outstanding Loan Obligations | B44: =Wages!G273 -> Nil
A45: =Wages!A275 -> Less part-payment of Salary made during mid month of | B45: =IF(B10=1,Wages!G275,"Not applicable") -> Not applicable
A46: =Wages!A277 -> Total Net Amount Due at End of Contract | B46: =Wages!G277 -> Nil
A47: =Wages!A279 -> Employer's Signature Confirming Payment of the Net Amount Due Following End of Contract | B47: ------------------------------------------
A48: =Wages!A281 -> Employee's Signature agreeing to the amount due following end of Contract | B48: ------------------------------------------
...

Sheet Wages
A2: Citi-Nati Supermarket | H2: Tax Rates WEF 1st April, 24
H3: 150000 | I3: 150001 | J3: 0 | K3: First
A4: Month to pay | C4: ='Pay Sheet'!C2 -> 1 | E4: Month Wages to Pay: | F4: =B$8 -> Mid | G4: =E18 -> January 2026 | H4: 350000 | I4: 350001 | J4: 0.25 | K4: Next | L4: =H4*J4 -> 87500
H5: 2050000 | I5: 2050001 | J5: 0.3 | K5: Next | L5: =H5*J5 -> 615000
A6: Position in month | C6: ='Pay Sheet'!C3 -> 1 | D6: 1 for mid, 2 for full month | H6: 2550000 | I6: 0 | J6: 0.35 | K6: Next
B8: =IF(C6=1,"Mid",IF(C6=2,"End","wrong entry")) -> Mid
B9: =IF(C4<9,E18,IF(C4=9,LoanSchedule!D67,IF(C4=10,LoanSchedule!D68,IF(C4=11,LoanSchedule!D69,IF(C4=12,LoanSchedule!D70,"wrong month"))))) -> January 2026 | C9: NB: for loans, overtime, days absent or termination of contracts, go to cells L141, C141 or K184 after the payslips
A11: 1 | B11: <---- position in month | G11: Half Pay | I11: Full Pay
E12: Total P.A.Y.E | G12: =I12/2 -> 0 | I12: =E203 -> 0
D13: Total wages to pay net of P.A.Y.E: | G13: =I13/2 -> 967000 | I13: =E207 -> 1934000
C15: Citi-Nati Shopping Centre | G15: Citi-Nati Shopping Centre | K15: Citi-Nati Shopping Centre | O15: Citi-Nati Shopping Centre
C16: Name of Employee: | D16: =CONCATENATE(+Biodata!B15,+" ",+Biodata!C15) -> Sapulene Mkulichi | G16: =C16 -> Name of Employee: | H16: =CONCATENATE(+Biodata!B16, +" ",+Biodata!C16) -> George Matemba | K16: Name of Employee: | L16: =CONCATENATE(+Biodata!B22,+" ",+Biodata!C22) -> Alinafe James | O16: Name of Employee: | P16: =CONCATENATE(+Biodata!B23,+" ",+Biodata!C23) -> Chimwemwe Banda
C17: Employee Number: | E17: =Biodata!A15 -> CITI01 | G17: Employee Number: | I17: =Biodata!A16 -> CITI02 | K17: Employee Number: | M17: =Biodata!A22 -> CITI04 | O17: Employee Number: | Q17: =Biodata!A23 -> CITI05
B18: =E18 -> January 2026 | C18: Payslip for the Month: | E18: =+IF(C4=1,LoanSchedule!D59,IF(C4=2,LoanSchedule!D60,IF(C4=3,LoanSchedule!D61,IF(C4=4,LoanSchedule!D62,IF(C4=5,LoanSchedule!D63,IF(C4=6,LoanSchedule!D64,IF(C4=7,LoanSchedule!D65,IF(C4=8,LoanSchedule!D66,B9)))))))) -> January 2026 | G18: Payslip for the Month: | I18: =$B$18 -> January 2026 | K18: Payslip for the Month: | M18: =$B$18 -> January 2026 | O18: Payslip for the Month: | Q18: =$B$18 -> January 2026
C19: Gross Salary | E19: =LoanSchedule!C14 -> 0 | G19: Gross Salary | I19: =LoanSchedule!D14 -> 120000 | K19: Gross Salary | M19: =LoanSchedule!F14 -> 80000 | O19: Gross Salary | Q19: =LoanSchedule!G14 -> 80000
C20: Overtime Claim | E20: =LoanSchedule!C20 -> 0 | G20: Overtime Claim | I20: =LoanSchedule!D20 -> 0 | K20: Overtime Claim | M20: =LoanSchedule!F20 -> 0 | O20: Overtime Claim | Q20: =LoanSchedule!G20 -> 0
C21: P.A.Y.E | D21: =IF(AND(SUM(E19-$H$3)<$I$3,E19<$I$3),0,IF(AND(SUM(E19-$H$3)<$I$4,E19>$I$3),SUM((E19-$H$3)*$J$4),IF(AND(SUM(E19-$H$3)<$I$5,E19>$I$4),SUM($L$4+(E19-$H$3-$H$4)*$J$5),SUM($L$4+$L$5+(E19-$H$3-$H$4-$H$5)*$J$6)))) -> 0 | G21: =C21 -> P.A.Y.E | H21: =IF(AND(SUM(I19-$H$3)<$I$3,I19<$I$3),0,IF(AND(SUM(I19-$H$3)<$I$4,I19>$I$3),SUM((I19-$H$3)*$J$4),IF(AND(SUM(I19-$H$3)<$I$5,I19>$I$4),SUM($L$4+(I19-$H$3-$H$4)*$J$5),SUM($L$4+$L$5+(I19-$H$3-$H$4-$H$5)*$J$6)))) -> 0 | K21: =C93 -> P.A.Y.E | L21: =IF(AND(SUM(M19-$H$3)<$I$3,M19<$I$3),0,IF(AND(SUM(M19-$H$3)<$I$4,M19>$I$3),SUM((M19-$H$3)*$J$4),IF(AND(SUM(M19-$H$3)<$I$5,M19>$I$4),SUM($L$4+(M19-$H$3-$H$4)*$J$5),SUM($L$4+$L$5+(M19-$H$3-$H$4-$H$5)*$J$6)))) -> 0 | O21: =K21 -> P.A.Y.E | P21: =IF(AND(SUM(Q19-$H$3)<$I$3,Q19<$I$3),0,IF(AND(SUM(Q19-$H$3)<$I$4,Q19>$I$3),SUM((Q19-$H$3)*$J$4),IF(AND(SUM(Q19-$H$3)<$I$5,Q19>$I$4),SUM($L$4+(Q19-$H$3-$H$4)*$J$5),SUM($L$4+$L$5+(Q19-$H$3-$H$4-$H$5)*$J$6)))) -> 0
C22: Xmas Gift/Leave Pay | E22: =LoanSchedule!C27 -> 0 | G22: =C22 -> Xmas Gift/Leave Pay | I22: =LoanSchedule!D27 -> 0 | K22: =C94 -> Xmas Gift/Leave Pay | L22: 0 | M22: =LoanSchedule!F27 -> 0 | O22: =K22 -> Xmas Gift/Leave Pay | Q22: =LoanSchedule!G27 -> 0
C23: Medical Aid Scheme | G23: Medical Aid Scheme | K23: Medical Aid Scheme | O23: Medical Aid Scheme
C24: Loan Instalment | D24: =LoanSchedule!C55 -> 0 | G24: =C24 -> Loan Instalment | H24: =+LoanSchedule!D55 -> 0 | K24: =C96 -> Loan Instalment | L24: =LoanSchedule!F55 -> 0 | O24: =K24 -> Loan Instalment | P24: =LoanSchedule!G55 -> 0
C25: Absence Deduction | D25: =ROUNDDOWN(LoanSchedule!C23,1) -> 0 | G25: =C25 -> Absence Deduction | H25: =ROUNDDOWN(LoanSchedule!D23,1) -> 0 | K25: =C97 -> Absence Deduction | L25: =ROUNDDOWN(LoanSchedule!F23,1) -> 0 | O25: =K25 -> Absence Deduction | P25: =ROUNDDOWN(LoanSchedule!G23,1) -> 0
C26: Total Deductions | D26: =SUM(D21:D25) -> 0 | G26: =C26 -> Total Deductions | H26: =SUM(H21:H25) -> 0 | K26: =C26 -> Total Deductions | L26: =SUM(L21:L25) -> 0 | O26: =K26 -> Total Deductions | P26: =+P24+P25 -> 0
C27: Loan Balance | D27: =LoanSchedule!C54 -> 0 | G27: =C27 -> Loan Balance | H27: =LoanSchedule!D54 -> 0 | K27: =C99 -> Loan Balance | L27: =LoanSchedule!F54 -> 0 | O27: =K27 -> Loan Balance | P27: =LoanSchedule!G54 -> 0
C29: Net Pay for the Month | E29: =SUM(E19+E20+E22-D26) -> 0 | G29: Net Pay for the Month | I29: =SUM(I19+I20+I22-H26) -> 120000 | K29: Net Pay for the Month | M29: =SUM(M19+M20+M22-L26) -> 80000 | O29: Net Pay for the Month | Q29: =SUM(Q19+Q20+Q22-P26) -> 80000
C30: Net Pay mid and end of Month | E30: =E29/2 -> 0 | G30: =C30 -> Net Pay mid and end of Month | I30: =I29/2 -> 60000 | K30: =C30 -> Net Pay mid and end of Month | M30: =M29/2 -> 40000 | O30: =C30 -> Net Pay mid and end of Month | Q30: =Q29/2 -> 40000
C33: Citi-Nati Shopping Centre | G33: Citi-Nati Shopping Centre | K33: Citi-Nati Shopping Centre | O33: Citi-Nati Shopping Centre
C34: Name of Employee: | D34: =CONCATENATE(+Biodata!B24,+" ",+Biodata!C24) -> vacant | G34: =C34 -> Name of Employee: | H34: =CONCATENATE(+Biodata!B25,+" ",+Biodata!C25) -> Maureen Ulaya | K34: Name of Employee: | L34: =CONCATENATE(+Biodata!B26,+" ",+Biodata!C26) -> Francis Chatsweka | O34: Name of Employee: | P34: =CONCATENATE(+Biodata!B27,+" ",+Biodata!C27) -> Stenala Mponda
C35: Employee Number: | E35: =Biodata!A24 -> CITI06 | G35: Employee Number: | I35: =Biodata!A25 -> CITI07 | K35: Employee Number: | M35: =Biodata!A26 -> CITI08 | O35: Employee Number: | Q35: =Biodata!A27 -> CITI09
C36: Payslip for the Month: | E36: =$B$18 -> January 2026 | G36: Payslip for the Month: | I36: =$B$18 -> January 2026 | K36: Payslip for the Month: | M36: =$B$18 -> January 2026 | O36: Payslip for the Month: | Q36: =$B$18 -> January 2026
C37: Gross Salary | E37: =LoanSchedule!H14 -> 0 | G37: Gross Salary | I37: =LoanSchedule!I14 -> 80000 | K37: Gross Salary | M37: =LoanSchedule!J14 -> 70000 | O37: Gross Salary | Q37: =LoanSchedule!K14 -> 70000
C38: Overtime Claim | D38: 0 | E38: =LoanSchedule!H20 -> 0 | G38: Overtime Claim | I38: =LoanSchedule!I20 -> 0 | K38: Overtime Claim | M38: =LoanSchedule!J20 -> 0 | O38: Overtime Claim | Q38: =LoanSchedule!K20 -> 0
C39: P.A.Y.E | D39: =IF(AND(SUM(E37-$H$3)<$I$3,E37<$I$3),0,IF(AND(SUM(E37-$H$3)<$I$4,E37>$I$3),SUM((E37-$H$3)*$J$4),IF(AND(SUM(E37-$H$3)<$I$5,E37>$I$4),SUM($L$4+(E37-$H$3-$H$4)*$J$5),SUM($L$4+$L$5+(E37-$H$3-$H$4-$H$5)*$J$6)))) -> 0 | G39: =C39 -> P.A.Y.E | H39: =IF(AND(SUM(I37-$H$3)<$I$3,I37<$I$3),0,IF(AND(SUM(I37-$H$3)<$I$4,I37>$I$3),SUM((I37-$H$3)*$J$4),IF(AND(SUM(I37-$H$3)<$I$5,I37>$I$4),SUM($L$4+(I37-$H$3-$H$4)*$J$5),SUM($L$4+$L$5+(I37-$H$3-$H$4-$H$5)*$J$6)))) -> 0 | K39: =K21 -> P.A.Y.E | L39: =IF(AND(SUM(M37-$H$3)<$I$3,M37<$I$3),0,IF(AND(SUM(M37-$H$3)<$I$4,M37>$I$3),SUM((M37-$H$3)*$J$4),IF(AND(SUM(M37-$H$3)<$I$5,M37>$I$4),SUM($L$4+(M37-$H$3-$H$4)*$J$5),SUM($L$4+$L$5+(M37-$H$3-$H$4-$H$5)*$J$6)))) -> 0 | O39: =O21 -> P.A.Y.E | P39: =IF(AND(SUM(Q37-$H$3)<$I$3,Q37<$I$3),0,IF(AND(SUM(Q37-$H$3)<$I$4,Q37>$I$3),SUM((Q37-$H$3)*$J$4),IF(AND(SUM(Q37-$H$3)<$I$5,Q37>$I$4),SUM($L$4+(Q37-$H$3-$H$4)*$J$5),SUM($L$4+$L$5+(Q37-$H$3-$H$4-$H$5)*$J$6)))) -> 0
C40: Xmas Gift/Leave Pay | E40: =LoanSchedule!H27 -> 0 | G40: =C40 -> Xmas Gift/Leave Pay | I40: =LoanSchedule!I27 -> 0 | K40: =K22 -> Xmas Gift/Leave Pay | M40: =LoanSchedule!J27 -> 0 | O40: =K40 -> Xmas Gift/Leave Pay | Q40: =LoanSchedule!K27 -> 0
C41: Medical Aid Scheme | G41: Medical Aid Scheme | K41: Medical Aid Scheme | O41: Medical Aid Scheme
C42: Loan Instalment | D42: =LoanSchedule!H55 -> 0 | G42: =C42 -> Loan Instalment | H42: =LoanSchedule!I55 -> 0 | K42: =K24 -> Loan Instalment | L42: =LoanSchedule!J55 -> 0 | O42: =K42 -> Loan Instalment | P42: =LoanSchedule!K55 -> 0
C43: Absence Deduction | D43: =ROUNDDOWN(LoanSchedule!H23,1) -> 0 | G43: =C43 -> Absence Deduction | H43: =ROUNDDOWN(LoanSchedule!I23,1) -> 0 | K43: =K25 -> Absence Deduction | L43: =ROUNDDOWN(LoanSchedule!J23,1) -> 0 | O43: =K43 -> Absence Deduction | P43: =ROUNDDOWN(LoanSchedule!K23,1) -> 0
C44: Total Deductions | D44: =SUM(D39:D43) -> 0 | G44: =G26 -> Total Deductions | H44: =SUM(H39:H43) -> 0 | K44: =K26 -> Total Deductions | L44: =SUM(L39:L43) -> 0 | O44: =K44 -> Total Deductions | P44: =+P42+P43 -> 0
C45: Loan Balance | D45: =LoanSchedule!H54 -> 0 | G45: =C45 -> Loan Balance | H45: =LoanSchedule!I54 -> 0 | K45: =K27 -> Loan Balance | L45: =LoanSchedule!J54 -> 0 | O45: =K45 -> Loan Balance | P45: =LoanSchedule!K54 -> 0
C47: Net Pay for the Month | E47: =SUM(E37+E38+E40-D44) -> 0 | G47: Net Pay for the Month | I47: =SUM(I37+I38+I40-H44) -> 80000 | K47: Net Pay for the Month | M47: =SUM(M37+M38+M40-L44) -> 70000 | O47: Net Pay for the Month | Q47: =SUM(Q37+Q38+Q40-P44) -> 70000
C48: Net Pay mid and end of Month | E48: =E47/2 -> 0 | G48: =C48 -> Net Pay mid and end of Month | I48: =I47/2 -> 40000 | K48: =C48 -> Net Pay mid and end of Month | M48: =M47/2 -> 35000 | O48: =C48 -> Net Pay mid and end of Month | Q48: =Q47/2 -> 35000
...

Sheet Re-Engagements
L1: (

Sheet LoanSchedule
A2: Citi-Nati Supermarket
A11: Employee list | C11: =Wages!D16 -> Sapulene Mkulichi | D11: =Wages!H16 -> George Matemba | E11: =Wages!P141 -> vacant | F11: =Wages!L16 -> Alinafe James | G11: =Wages!P16 -> Chimwemwe Banda | H11: =Wages!D34 -> vacant | I11: =Wages!H34 -> Maureen Ulaya | J11: =Wages!L34 -> Francis Chatsweka | K11: =Wages!P34 -> Stenala Mponda | L11: =Wages!D52 -> Simikizani Siki | M11: =Wages!H52 -> Amini Wecha | N11: =Wages!L52 -> Tayifolo Mandowa | O11: =Wages!P52 -> Monica George | P11: =Wages!D70 -> Madalitso Baluti | Q11: =Wages!H70 -> Peter James | R11: =Wages!L70 -> Maggie Billy | S11: =Wages!P70 -> vacant | T11: =Wages!D88 -> Esnat Adam | U11: =Wages!H88 -> Martin Kandalama | V11: =Wages!L88 -> Daniel Mponda | W11: =Wages!P88 -> Elizabeth Kabudula | X11: =Wages!D106 -> vacant | Y11: =Wages!H106 -> William Mahinya | Z11: =Wages!L106 -> vacant | AA11: =Wages!P106 | AB11: =Wages!D123 -> vacant | AC11: =Wages!H123 -> Yankho Gulani | AD11: =Wages!L123 -> Agness Mponda | AE11: =Wages!P123 -> Elizabeth Chinkono | AF11: =Wages!D141 -> vacant | AG11: =Wages!H141 -> Dancan Botha | AH11: =Wages!L141 -> Ibrahim Amadu
A12: Employee Number | C12: =Biodata!A15 -> CITI01 | D12: =Biodata!A16 -> CITI02 | E12: =Biodata!A17 -> CITI03 | F12: =Biodata!A22 -> CITI04 | G12: =Biodata!A23 -> CITI05 | H12: =Biodata!A24 -> CITI06 | I12: =Biodata!A25 -> CITI07 | J12: =Biodata!A26 -> CITI08 | K12: =Biodata!A27 -> CITI09 | L12: =Biodata!A28 -> CITI10 | M12: =Biodata!A29 -> CITI11 | N12: =Biodata!A35 -> CITI12 | O12: =Biodata!A36 -> CITI13 | P12: =Biodata!A37 -> CITI14 | Q12: =Biodata!A43 -> CITI15 | R12: =Biodata!A44 -> CITI16 | S12: =Biodata!A45 -> CITI17 | T12: =Biodata!A46 -> CITI18 | U12: =Biodata!A53 -> CITI19 | V12: =Biodata!A54 -> CITI20 | W12: =Biodata!A55 -> CITI21 | X12: =Biodata!A56 -> CITI22 | Y12: =Biodata!A62 -> CITI23 | Z12: =Biodata!A63 -> CITI24 | AA12: =Biodata!A64 -> CITI25 | AB12: =Biodata!A65 -> CITI26 | AC12: =Biodata!A66 -> CITI27 | AD12: =Biodata!A73 -> CITI28 | AE12: =Biodata!A74 -> CITI29 | AF12: =Biodata!A75 -> CITI30 | AG12: =Biodata!A76 -> CITI30 | AH12: =Biodata!A77 -> CITI31
A14: Agreed Salary per Month | C14: =Biodata!F15 -> 0 | D14: =Biodata!$F16 -> 120000 | E14: =Biodata!$F17 -> 0 | F14: =Biodata!F22 -> 80000 | G14: =Biodata!$F23 -> 80000 | H14: =Biodata!$F24 -> 0 | I14: =Biodata!$F25 -> 80000 | J14: =Biodata!$F26 -> 70000 | K14: =Biodata!$F27 -> 70000 | L14: =Biodata!F28 -> 70000 | M14: =Biodata!F29 -> 70000 | N14: =Biodata!$F35 -> 120000 | O14: =Biodata!$F36 -> 80000 | P14: =Biodata!F37 -> 90000 | Q14: =Biodata!$F43 -> 60000 | R14: =Biodata!F44 -> 80000 | S14: =Biodata!F45 -> 0 | T14: =Biodata!F46 -> 80000 | U14: =Biodata!$F53 -> 70000 | V14: =Biodata!$F54 -> 70000 | W14: =Biodata!F55 -> 20000 | X14: =Biodata!F56 -> 0 | Y14: =Biodata!$F62 -> 150000 | Z14: =Biodata!$F63 -> 0 | AA14: =Biodata!$F64 -> 0 | AB14: =Biodata!$F65 -> 0 | AC14: =Biodata!$F66 -> 120000 | AD14: =Biodata!$F73 -> 80000 | AE14: =Biodata!$F74 -> 100000 | AF14: =Biodata!$F75 -> 0 | AG14: =Biodata!$F76 -> 94000 | AH14: =Biodata!$F77 -> 80000
A15: Agreed Working Days per Month | D15: 28
A16: Pressumed Daily Rate | C16: =INT(ROUND(C14/$D$15,1)) -> 0 | D16: =INT(ROUND(D14/$D$15,1)) -> 4285 | E16: =INT(ROUND(E14/$D$15,1)) -> 0 | F16: =INT(ROUND(F14/$D$15,1)) -> 2857 | G16: =INT(ROUND(G14/$D$15,1)) -> 2857 | H16: =INT(ROUND(H14/$D$15,1)) -> 0 | I16: =INT(ROUND(I14/$D$15,1)) -> 2857 | J16: =INT(ROUND(J14/$D$15,1)) -> 2500 | ... AH16: =INT(ROUND(AH14/$D$15,1)) -> 2857
A17: Presumed Hourly Rate | C17: =INT(ROUND(C16/8,1)) -> 0 | D17: =INT(ROUND(D16/8,1)) -> 535 | E17: =INT(ROUND(E16/8,1)) -> 0 | F17: =INT(ROUND(F16/8,1)) -> 357 | G17: =INT(ROUND(G16/8,1)) -> 357 | H17: =INT(ROUND(H16/8,1)) -> 0 | I17: =INT(ROUND(I16/8,1)) -> 357 | J17: =INT(ROUND(J16/8,1)) -> 312 | ... AH17: =INT(ROUND(AH16/8,1)) -> 357
A18: Normal Overtime Worked | C18: =C17*Wages!$C162 -> 0 | D18: =C17*Wages!$C163 -> 0 | E18: =D17*Wages!$C164 -> 0 | F18: =F17*Wages!$C165 -> 0 | G18: =G17*Wages!$C1656 -> 0 | H18: =H17*Wages!$C167 -> 0 | I18: =I17*Wages!$C168 -> 0 | J18: =J17*Wages!$C169 -> 0 | K18: =K17*Wages!$C170 -> 0 | L18: =L17*Wages!$C171 -> 0 | M18: =M17*Wages!$C172 -> 0 | N18: =N17*Wages!$C173 -> 0 | O18: =O17*Wages!$C174 -> 0 | P18: =P17*Wages!$C175 -> 0 | Q18: =Q17*Wages!$C176 -> 0 | R18: =R17*Wages!$C177 -> 0 | S18: =S17*Wages!$C178 -> 0 | T18: =T17*Wages!$C179 -> 0 | U18: =U17*Wages!$C180 -> 0 | V18: =V17*Wages!$C181 -> 0 | W18: =W17*Wages!$C182 -> 0 | X18: =X17*Wages!$C183 -> 0 | Y18: =Y17*Wages!$C184 -> 0 | Z18: =Z17*Wages!$C185 -> 0 | AA18: =AA17*Wages!$C186 -> 0 | AB18: =AB17*Wages!$C187 -> 0 | AC18: =AC17*Wages!$C188 -> 0 | AD18: =AD17*Wages!$C189 -> 0 | AE18: =AE17*Wages!$C190 -> 0 | AF18: =AF17*Wages!$C191 -> 0 | AG18: =AG17*Wages!$C192 -> 0 | AH18: =AH17*Wages!$C193 -> 0
A19: Double Overtime Worked | C19: =C17*Wages!$C162*1.5 -> 0 | D19: =C17*Wages!$C163*1.5 -> 0 | E19: =D17*Wages!$C164*1.5 -> 0 | F19: =F17*Wages!$C165*1.5 -> 0 | G19: =G17*Wages!$C166*1.5 -> 0 | H19: =H17*Wages!$C167*1.5 -> 0 | I19: =I17*Wages!$C168*1.5 -> 0 | J19: =J17*Wages!$C169*1.5 -> 0 | K19: =K17*Wages!$C170*1.5 -> 0 | L19: =L17*Wages!$C171*1.5 -> 0 | M19: =M17*Wages!$C172*1.5 -> 0 | N19: =N17*Wages!$C173*1.5 -> 0 | O19: =O17*Wages!$C174*1.5 -> 0 | P19: =P17*Wages!$C175*1.5 -> 0 | Q19: =Q17*Wages!$C176*1.5 -> 0 | R19: =R17*Wages!$C177*1.5 -> 0 | S19: =S17*Wages!$C178*1.5 -> 0 | T19: =T17*Wages!$C179*1.5 -> 0 | U19: =U17*Wages!$C180*1.5 -> 0 | V19: =V17*Wages!$C181*1.5 -> 0 | W19: =W17*Wages!$C182*1.5 -> 0 | X19: =X17*Wages!$C183*1.5 -> 0 | Y19: =Y17*Wages!$C184*1.5 -> 0 | Z19: =Z17*Wages!$C185*1.5 -> 0 | AA19: =AA17*Wages!$C186*1.5 -> 0 | AB19: =AB17*Wages!$C187*1.5 -> 0 | AC19: =AC17*Wages!$C188*1.5 -> 0 | AD19: =AD17*Wages!$C189*1.5 -> 0 | AE19: =AE17*Wages!$C190*1.5 -> 0 | AF19: =AF17*Wages!$C191*1.5 -> 0 | AG19: =AG17*Wages!$C192*1.5 -> 0 | AH19: =AH17*Wages!$C193*1.5 -> 0
A20: Total Overtime Claim | C20: =C18+C19 -> 0 | D20: =D18+D19 -> 0 | E20: =E18+E19 -> 0 | F20: =F18+F19 -> 0 | G20: =G18+G19 -> 0 | H20: =H18+H19 -> 0 | I20: =I18+I19 -> 0 | J20: =J18+J19 -> 0 | ... AH20: =AH18+AH19 -> 0
A21: Days absent | C21: =Wages!$E162 -> 0 | D21: =Wages!$E162 -> 0 | E21: =Wages!$E162 -> 0 | F21: =Wages!$E164 -> 0 | G21: =Wages!$E165 -> 0 | H21: =Wages!$E166 -> 0 | I21: =Wages!$E167 -> 0 | J21: =Wages!$E168 -> 0 | K21: =Wages!$E169 -> 0 | L21: =Wages!$E170 -> 0 | M21: =Wages!$E171 -> 0 | N21: =Wages!$E172 -> 0 | O21: =Wages!$E173 -> 0 | P21: =Wages!$E174 -> 0 | Q21: =Wages!$E175 -> 0 | R21: =Wages!$E176 -> 0 | S21: =Wages!$E177 -> 0 | T21: =Wages!$E178 -> 0 | U21: =Wages!$E179 -> 0 | V21: =Wages!$E180 -> 0 | W21: =Wages!$E181 -> 0 | X21: =Wages!$E178 -> 0 | Y21: =Wages!$E179 -> 0 | Z21: =Wages!$E180 -> 0 | AA21: =Wages!$E181 -> 0 | AB21: =Wages!$E181 -> 0 | AC21: =Wages!$E181 -> 0 | AD21: =Wages!$E181 -> 0 | AE21: =Wages!$E181 -> 0 | AF21: =Wages!$E181 -> 0 | AG21: =Wages!$E181 -> 0 | AH21: =Wages!$E181 -> 0
A23: Amount to deduct | C23: =C16*C21 -> 0 | D23: =D16*D21 -> 0 | E23: =E16*E21 -> 0 | F23: =F16*F21 -> 0 | G23: =G16*G21 -> 0 | H23: =H16*H21 -> 0 | I23: =I16*I21 -> 0 | J23: =J16*J21 -> 0 | ... AH23: =AH16*AH21 -> 0
A25: Gift factor | C25: 0 | D25: 0 | E25: 0 | F25: 0 | G25: 0 | H25: 0 | I25: 0 | J25: 0 | K25: 0 | L25: 0 | M25: 0 | N25: 0 | O25: 0 | P25: 0 | Q25: 0 | R25: 0 | S25: 0 | T25: 0 | U25: 0 | V25: 0 | W25: 0 | X25: 0 | Y25: 0 | Z25: 0 | AA25: 0 | AB25: 0 | AC25: 0 | AD25: 0 | AE25: 0 | AF25: 0 | AG25: 0 | AH25: 0
A27: Gifts | C27: =+C25*C14 -> 0 | D27: =+D25*D14 -> 0 | E27: =+E25*E14 -> 0 | F27: =+F25*F14 -> 0 | G27: =+G25*G14 -> 0 | H27: =+H25*H14 -> 0 | I27: =+I25*I14 -> 0 | J27: =+J25*J14 -> 0 | ... AH27: =+AH25*AH14 -> 0
A29: Month loan granted | C29: =IF(Wages!$M162="recommend for approval",Wages!$G162,0) -> 0 | D29: =IF(Wages!$M163="recommend for approval",Wages!$G163,0) -> 0 | E29: =IF(Wages!$M164="recommend for approval",Wages!$G164,0) -> 0 | F29: =IF(Wages!$M165="recommend for approval",Wages!$G165,0) -> 0 | G29: =IF(Wages!$M166="recommend for approval",Wages!$G166,0) -> 0 | H29: =IF(Wages!$M167="recommend for approval",Wages!$G167,0) -> 0 | I29: =IF(Wages!$M168="recommend for approval",Wages!$G168,0) -> 0 | J29: =IF(Wages!$M169="recommend for approval",Wages!$G169,0) -> 0 | K29: =IF(Wages!$M170="recommend for approval",Wages!$G170,0) -> 0 | L29: =IF(Wages!$M171="recommend for approval",Wages!$G171,0) -> 0 | M29: =IF(Wages!$M172="recommend for approval",Wages!$G172,0) -> 0 | N29: =IF(Wages!$M173="recommend for approval",Wages!$G173,0) -> 0 | O29: =IF(Wages!$M174="recommend for approval",Wages!$G174,0) -> 0 | P29: =IF(Wages!$M175="recommend for approval",Wages!$G175,0) -> 0 | Q29: =IF(Wages!$M176="recommend for approval",Wages!$G176,0) -> 0 | R29: =IF(Wages!$M177="recommend for approval",Wages!$G177,0) -> 0 | S29: =IF(Wages!$M178="recommend for approval",Wages!$G178,0) -> 0 | T29: =IF(Wages!$M179="recommend for approval",Wages!$G179,0) -> 0 | U29: =IF(Wages!$M180="recommend for approval",Wages!$G180,0) -> 0 | V29: =IF(Wages!$M181="recommend for approval",Wages!$G181,0) -> 0 | W29: =IF(Wages!$M182="recommend for approval",Wages!$G182,0) -> 0 | X29: =IF(Wages!$M183="recommend for approval",Wages!$G183,0) -> 0 | Y29: =IF(Wages!$M184="recommend for approval",Wages!$G184,0) -> 0 | Z29: =IF(Wages!$M185="recommend for approval",Wages!$G185,0) -> 0 | AA29: =IF(Wages!$M186="recommend for approval",Wages!$G186,0) -> 0 | AB29: =IF(Wages!$M187="recommend for approval",Wages!$G187,0) -> 0 | AC29: =IF(Wages!$M188="recommend for approval",Wages!$G188,0) -> 0 | AD29: =IF(Wages!$M189="recommend for approval",Wages!$G189,0) -> 0 | AE29: =IF(Wages!$M190="recommend for approval",Wages!$G190,0) -> 0 | AF29: =IF(Wages!$M191="recommend for approval",Wages!$G191,0) -> 0 | AG29: =IF(Wages!$M192="recommend for approval",Wages!$G192,0) -> 0 | AH29: =IF(Wages!$M193="recommend for approval",Wages!$G193,0) -> 0
A31: Agreed period to repay | C31: =IF(Wages!$M162="recommend for approval",Wages!$I162,0) -> 0 | D31: =IF(Wages!$M163="recommend for approval",Wages!$I163,0) -> 0 | E31: =IF(Wages!$M164="recommend for approval",Wages!$I164,0) -> 0 | F31: =IF(Wages!$M165="recommend for approval",Wages!$I165,0) -> 0 | G31: =IF(Wages!$M166="recommend for approval",Wages!$I166,0) -> 0 | H31: =IF(Wages!$M167="recommend for approval",Wages!$I167,0) -> 0 | I31: =IF(Wages!$M168="recommend for approval",Wages!$I168,0) -> 0 | J31: =IF(Wages!$M169="recommend for approval",Wages!$I169,0) -> 0 | K31: =IF(Wages!$M170="recommend for approval",Wages!$I170,0) -> 0 | L31: =IF(Wages!$M171="recommend for approval",Wages!$I171,0) -> 0 | M31: =IF(Wages!$M172="recommend for approval",Wages!$I172,0) -> 0 | N31: =IF(Wages!$M173="recommend for approval",Wages!$I173,0) -> 0 | O31: =IF(Wages!$M174="recommend for approval",Wages!$I174,0) -> 0 | P31: =IF(Wages!$M175="recommend for approval",Wages!$I175,0) -> 0 | Q31: =IF(Wages!$M176="recommend for approval",Wages!$I176,0) -> 0 | R31: =IF(Wages!$M177="recommend for approval",Wages!$I177,0) -> 0 | S31: =IF(Wages!$M178="recommend for approval",Wages!$I178,0) -> 0 | T31: =IF(Wages!$M179="recommend for approval",Wages!$I179,0) -> 0 | U31: =IF(Wages!$M180="recommend for approval",Wages!$I180,0) -> 0 | V31: =IF(Wages!$M181="recommend for approval",Wages!$I181,0) -> 0 | W31: =IF(Wages!$M182="recommend for approval",Wages!$I182,0) -> 0 | X31: =IF(Wages!$M183="recommend for approval",Wages!$I183,0) -> 0 | Y31: =IF(Wages!$M184="recommend for approval",Wages!$I184,0) -> 0 | Z31: =IF(Wages!$M185="recommend for approval",Wages!$I185,0) -> 0 | AA31: =IF(Wages!$M186="recommend for approval",Wages!$I186,0) -> 0 | AB31: =IF(Wages!$M187="recommend for approval",Wages!$I187,0) -> 0 | AC31: =IF(Wages!$M188="recommend for approval",Wages!$I188,0) -> 0 | AD31: =IF(Wages!$M189="recommend for approval",Wages!$I189,0) -> 0 | AE31: =IF(Wages!$M190="recommend for approval",Wages!$I190,0) -> 0 | AF31: =IF(Wages!$M191="recommend for approval",Wages!$I191,0) -> 0 | AG31: =IF(Wages!$M192="recommend for approval",Wages!$I192,0) -> 0 | AH31: =IF(Wages!$M193="recommend for approval",Wages!$I193,0) -> 0
A32: Loan interest rate applied | C32: 0.05
C33: Loan Calculations | N33: Loan Calculations
C35: =C11 -> Sapulene Mkulichi | D35: =D11 -> George Matemba | E35: =E11 -> vacant | F35: =F11 -> Alinafe James | G35: =G11 -> Chimwemwe Banda | H35: =H11 -> vacant | I35: =I11 -> Maureen Ulaya | J35: =J11 -> Francis Chatsweka | ... AH35: =AH11 -> Ibrahim Amadu
A36: Loan outstanding | C36: =IF(Wages!$M162="recommend for approval",Wages!$H162,0) -> 0 | D36: =IF(Wages!$M164="recommend for approval",Wages!$H164,0) -> 0 | E36: =IF(Wages!$M164="recommend for approval",Wages!$H164,0) -> 0 | F36: =IF(Wages!$M165="recommend for approval",Wages!$H165,0) -> 0 | G36: =IF(Wages!$M166="recommend for approval",Wages!$H166,0) -> 0 | H36: 0 | I36: =IF(Wages!$M168="recommend for approval",Wages!$H168,0) -> 0 | J36: =IF(Wages!$M169="recommend for approval",Wages!$H169,0) -> 0 | K36: =IF(Wages!$M170="recommend for approval",Wages!$H170,0) -> 0 | L36: =IF(Wages!$M171="recommend for approval",Wages!$H171,0) -> 0 | M36: =IF(Wages!$M172="recommend for approval",Wages!$H172,0) -> 0 | N36: 0 | O36: =IF(Wages!$M174="recommend for approval",Wages!$H174,0) -> 0 | P36: 0 | Q36: =IF(Wages!$M176="recommend for approval",Wages!$H176,0) -> 0 | R36: =IF(Wages!$M177="recommend for approval",Wages!$H177,0) -> 0 | S36: =IF(Wages!$M178="recommend for approval",Wages!$H178,0) -> 0 | T36: 0 | U36: =IF(Wages!$M180="recommend for approval",Wages!$H180,0) -> 0 | V36: =IF(Wages!$M181="recommend for approval",Wages!$H181,0) -> 0 | W36: =IF(Wages!$M182="recommend for approval",Wages!$H182,0) -> 0 | X36: =IF(Wages!$M183="recommend for approval",Wages!$H183,0) -> 0 | Y36: =IF(Wages!$M184="recommend for approval",Wages!$H184,0) -> 0 | Z36: =IF(Wages!$M185="recommend for approval",Wages!$H184,0) -> 0 | AA36: =IF(Wages!$M186="recommend for approval",Wages!$H186,0) -> 0 | AB36: =IF(Wages!$M187="recommend for approval",Wages!$H187,0) -> 0 | AC36: =IF(Wages!$M188="recommend for approval",Wages!$H188,0) -> 0 | AD36: =IF(Wages!$M189="recommend for approval",Wages!$H189,0) -> 0 | AE36: =IF(Wages!$M190="recommend for approval",Wages!$H190,0) -> 0 | AF36: =IF(Wages!$M191="recommend for approval",Wages!$H191,0) -> 0 | AG36: =IF(Wages!$M192="recommend for approval",Wages!$H192,0) -> 0 | AH36: =IF(Wages!$M193="recommend for approval",Wages!$H193,0) -> 0
A37: Top-Up | C37: 0 | D37: 0 | E37: 0 | F37: 0 | G37: 0 | H37: 0 | I37: 0 | J37: 0 | K37: 0 | L37: 0 | M37: 0 | N37: 0 | O37: 0 | P37: 0 | Q37: 0 | R37: 0 | S37: 0 | T37: 0 | U37: 0 | V37: 0 | W37: 0 | X37: 0 | Y37: 0 | Z37: 0 | AA37: 0 | AB37: 0 | AC37: 0 | AD37: 0 | AE37: 0 | AF37: 0 | AG37: 0 | AH37: 0
A38: Month loan granted | C38: =C29 -> 0 | D38: =D29 -> 0 | E38: =E29 -> 0 | F38: =F29 -> 0 | G38: =G29 -> 0 | H38: =H29 -> 0 | I38: =I29 -> 0 | J38: =J29 -> 0 | ... AH38: =AH29 -> 0
A39: Total before deduction | C39: =+SUM(C36:C37) -> 0 | D39: =+SUM(D36:D37) -> 0 | E39: =+SUM(E36:E37) -> 0 | F39: =+SUM(F36:F37) -> 0 | G39: =+SUM(G36:G37) -> 0 | H39: =+SUM(H36:H37) -> 0 | I39: =+SUM(I36:I37) -> 0 | J39: =+SUM(J36:J37) -> 0 | ... AH39: =+SUM(AH36:AH37) -> 0
A40: Agreed period to repay | C40: =C31 -> 0 | D40: =D31 -> 0 | E40: =E31 -> 0 | F40: =F31 -> 0 | G40: =G31 -> 0 | H40: =H31 -> 0 | I40: =I31 -> 0 | J40: =J31 -> 0 | ... AH40: =AH31 -> 0
A41: Month repayment starts | C41: =+IF(C38=1,"February",IF(C38=2,"March",IF(C38=3,"April",IF(C38=4,"May",IF(C38=5,"June",IF(C38=6,"July",IF(C38=7,"August",IF(C38=8,"September",IF(C38=9,"October",IF(C38=10,"November",IF(C38=11,"December",IF(C38=12,"January","N/A")))))))))))) -> N/A | D41: =+IF(D38=1,"February",IF(D38=2,"March",IF(D38=3,"April",IF(D38=4,"May",IF(D38=5,"June",IF(D38=6,"July",IF(D38=7,"August",IF(D38=8,"September",IF(D38=9,"October",IF(D38=10,"November",IF(D38=11,"December",IF(D38=12,"January","N/A")))))))))))) -> N/A | E41: =+IF(E38=1,"February",IF(E38=2,"March",IF(E38=3,"April",IF(E38=4,"May",IF(E38=5,"June",IF(E38=6,"July",IF(E38=7,"August",IF(E38=8,"September",IF(E38=9,"October",IF(E38=10,"November",IF(E38=11,"December",IF(E38=12,"January","N/A")))))))))))) -> N/A | F41: =+IF(F38=1,"February",IF(F38=2,"March",IF(F38=3,"April",IF(F38=4,"May",IF(F38=5,"June",IF(F38=6,"July",IF(F38=7,"August",IF(F38=8,"September",IF(F38=9,"October",IF(F38=10,"November",IF(F38=11,"December",IF(F38=12,"January","N/A")))))))))))) -> N/A | G41: =+IF(G38=1,"February",IF(G38=2,"March",IF(G38=3,"April",IF(G38=4,"May",IF(G38=5,"June",IF(G38=6,"July",IF(G38=7,"August",IF(G38=8,"September",IF(G38=9,"October",IF(G38=10,"November",IF(G38=11,"December",IF(G38=12,"January","N/A")))))))))))) -> N/A | H41: =+IF(H38=1,"February",IF(H38=2,"March",IF(H38=3,"April",IF(H38=4,"May",IF(H38=5,"June",IF(H38=6,"July",IF(H38=7,"August",IF(H38=8,"September",IF(H38=9,"October",IF(H38=10,"November",IF(H38=11,"December",IF(H38=12,"January","N/A")))))))))))) -> N/A | I41: =+IF(I38=1,"February",IF(I38=2,"March",IF(I38=3,"April",IF(I38=4,"May",IF(I38=5,"June",IF(I38=6,"July",IF(I38=7,"August",IF(I38=8,"September",IF(I38=9,"October",IF(I38=10,"November",IF(I38=11,"December",IF(I38=12,"January","N/A")))))))))))) -> N/A | J41: =+IF(J38=1,"February",IF(J38=2,"March",IF(J38=3,"April",IF(J38=4,"May",IF(J38=5,"June",IF(J38=6,"July",IF(J38=7,"August",IF(J38=8,"September",IF(J38=9,"October",IF(J38=10,"November",IF(J38=11,"December",IF(J38=12,"January","N/A")))))))))))) -> N/A | ... AH41: =+IF(AH38=1,"February",IF(AH38=2,"March",IF(AH38=3,"April",IF(AH38=4,"May",IF(AH38=5,"June",IF(AH38=6,"July",IF(AH38=7,"August",IF(AH38=8,"September",IF(AH38=9,"October",IF(AH38=10,"November",IF(AH38=11,"December",IF(AH38=12,"January","N/A")))))))))))) -> N/A
A42: Month repayment ends | C42: =+IF(C38=0,"N/A",IF(SUM(C38+C40)>12,SUM(C38+C40-12),SUM(C38+C40))) -> N/A | D42: =+IF(D38=0,"N/A",IF(SUM(D38+D40)>12,SUM(D38+D40-12),SUM(D38+D40))) -> N/A | E42: =+IF(E38=0,"N/A",IF(SUM(E38+E40)>12,SUM(E38+E40-12),SUM(E38+E40))) -> N/A | F42: =+IF(F38=0,"N/A",IF(SUM(F38+F40)>12,SUM(F38+F40-12),SUM(F38+F40))) -> N/A | G42: =+IF(G38=0,"N/A",IF(SUM(G38+G40)>12,SUM(G38+G40-12),SUM(G38+G40))) -> N/A | H42: =+IF(H38=0,"N/A",IF(SUM(H38+H40)>12,SUM(H38+H40-12),SUM(H38+H40))) -> N/A | I42: =+IF(I38=0,"N/A",IF(SUM(I38+I40)>12,SUM(I38+I40-12),SUM(I38+I40))) -> N/A | J42: =+IF(J38=0,"N/A",IF(SUM(J38+J40)>12,SUM(J38+J40-12),SUM(J38+J40))) -> N/A | ... AH42: =+IF(AH38=0,"N/A",IF(SUM(AH38+AH40)>12,SUM(AH38+AH40-12),SUM(AH38+AH40))) -> N/A
A43: Month repayment ends | C43: =IF(C42=1,"January ",IF(C42=2,"February ",IF(C42=3,"March ",IF(C42=4,"April ",IF(C42=5,"May ",IF(C42=6,"June ",IF(C42=7,"July ",IF(C42=8,"August ",IF(C42=9,"September ",IF(C42=10,"October ",IF(C42=11,"November ",IF(C42=12,"December ","N/A")))))))))))) -> N/A | D43: =IF(D42=1,"January ",IF(D42=2,"February ",IF(D42=3,"March ",IF(D42=4,"April ",IF(D42=5,"May ",IF(D42=6,"June ",IF(D42=7,"July ",IF(D42=8,"August ",IF(D42=9,"September ",IF(D42=10,"October ",IF(D42=11,"November ",IF(D42=12,"December ","N/A")))))))))))) -> N/A | E43: =IF(E42=1,"January ",IF(E42=2,"February ",IF(E42=3,"March ",IF(E42=4,"April ",IF(E42=5,"May ",IF(E42=6,"June ",IF(E42=7,"July ",IF(E42=8,"August ",IF(E42=9,"September ",IF(E42=10,"October ",IF(E42=11,"November ",IF(E42=12,"December ","N/A")))))))))))) -> N/A | F43: =IF(F42=1,"January ",IF(F42=2,"February ",IF(F42=3,"March ",IF(F42=4,"April ",IF(F42=5,"May ",IF(F42=6,"June ",IF(F42=7,"July ",IF(F42=8,"August ",IF(F42=9,"September ",IF(F42=10,"October ",IF(F42=11,"November ",IF(F42=12,"December ","N/A")))))))))))) -> N/A | G43: =IF(G42=1,"January ",IF(G42=2,"February ",IF(G42=3,"March ",IF(G42=4,"April ",IF(G42=5,"May ",IF(G42=6,"June ",IF(G42=7,"July ",IF(G42=8,"August ",IF(G42=9,"September ",IF(G42=10,"October ",IF(G42=11,"November ",IF(G42=12,"December ","N/A")))))))))))) -> N/A | H43: =IF(H42=1,"January ",IF(H42=2,"February ",IF(H42=3,"March ",IF(H42=4,"April ",IF(H42=5,"May ",IF(H42=6,"June ",IF(H42=7,"July ",IF(H42=8,"August ",IF(H42=9,"September ",IF(H42=10,"October ",IF(H42=11,"November ",IF(H42=12,"December ","N/A")))))))))))) -> N/A | I43: =IF(I42=1,"January ",IF(I42=2,"February ",IF(I42=3,"March ",IF(I42=4,"April ",IF(I42=5,"May ",IF(I42=6,"June ",IF(I42=7,"July ",IF(I42=8,"August ",IF(I42=9,"September ",IF(I42=10,"October ",IF(I42=11,"November ",IF(I42=12,"December ","N/A")))))))))))) -> N/A | J43: =IF(J42=1,"January ",IF(J42=2,"February ",IF(J42=3,"March ",IF(J42=4,"April ",IF(J42=5,"May ",IF(J42=6,"June ",IF(J42=7,"July ",IF(J42=8,"August ",IF(J42=9,"September ",IF(J42=10,"October ",IF(J42=11,"November ",IF(J42=12,"December ","N/A")))))))))))) -> N/A | ... AH43: =IF(AH42=1,"January ",IF(AH42=2,"February ",IF(AH42=3,"March ",IF(AH42=4,"April ",IF(AH42=5,"May ",IF(AH42=6,"June ",IF(AH42=7,"July ",IF(AH42=8,"August ",IF(AH42=9,"September ",IF(AH42=10,"October ",IF(AH42=11,"November ",IF(AH42=12,"December ","N/A")))))))))))) -> N/A
A44: Year repayment ends | C44: =IF(C38>C42,$B$71,IF(C38=C42,$B$71,$B$59)) -> 2026 | D44: =IF(D38>D42,$B$71,IF(D38=D42,$B$71,$B$59)) -> 2026 | E44: =IF(E38>E42,$B$71,IF(E38=E42,$B$71,$B$59)) -> 2026 | F44: =IF(F38>F42,$B$71,IF(F38=F42,$B$71,$B$59)) -> 2026 | G44: =IF(G38>G42,$B$71,IF(G38=G42,$B$71,$B$59)) -> 2026 | H44: =IF(H38>H42,$B$71,IF(H38=H42,$B$71,$B$59)) -> 2026 | I44: =IF(I38>I42,$B$71,IF(I38=I42,$B$71,$B$59)) -> 2026 | J44: =IF(J38>J42,$B$71,IF(J38=J42,$B$71,$B$59)) -> 2026 | ... AH44: =IF(AH38>AH42,$B$71,IF(AH38=AH42,$B$71,$B$59)) -> 2026
A45: Month repayment ends | C45: =IF(C39=0,"N/A",CONCATENATE(C43,C44)) -> N/A | D45: =IF(D39=0,"N/A",CONCATENATE(D43,D44)) -> N/A | E45: =IF(E39=0,"N/A",CONCATENATE(E43,E44)) -> N/A | F45: =IF(F39=0,"N/A",CONCATENATE(F43,F44)) -> N/A | G45: =IF(G39=0,"N/A",CONCATENATE(G43,G44)) -> N/A | H45: =IF(H39=0,"N/A",CONCATENATE(H43,H44)) -> N/A | I45: =IF(I39=0,"N/A",CONCATENATE(I43,I44)) -> N/A | J45: =IF(J39=0,"N/A",CONCATENATE(J43,J44)) -> N/A | ... AH45: =IF(AH39=0,"N/A",CONCATENATE(AH43,AH44)) -> N/A
A46: Total amount borrowed | C46: =+C36+C37 -> 0 | D46: =+D36+D37 -> 0 | E46: =+E36+E37 -> 0 | F46: =+F36+F37 -> 0 | G46: =+G36+G37 -> 0 | H46: =+H36+H37 -> 0 | I46: =+I36+I37 -> 0 | J46: =+J36+J37 -> 0 | ... AH46: =+AH36+AH37 -> 0
A47: Repayment amount | C47: =+IF(C39=0,"N/A",SUM(C46/C40+C46/C40*C32)) -> N/A | D47: =+IF(D39=0,"N/A",SUM(D46/D40+D46/D40*$C$32)) -> N/A | E47: =+IF(E39=0,"N/A",SUM(E46/E40+E46/E40*$C$32)) -> N/A | F47: =+IF(F39=0,"N/A",SUM(F46/F40+F46/F40*$C$32)) -> N/A | G47: =+IF(G39=0,"N/A",SUM(G46/G40+G46/G40*$C$32)) -> N/A | H47: =+IF(H39=0,"N/A",SUM(H46/H40+H46/H40*$C$32)) -> N/A | I47: =+IF(I39=0,"N/A",SUM(I46/I40+I46/I40*$C$32)) -> N/A | J47: =+IF(J39=0,"N/A",SUM(J46/J40+J46/J40*$C$32)) -> N/A | K47: =+IF(K39=0,"N/A",SUM(K46/K40+K46/K40*$C$32)) -> N/A | ... AH47: =+IF(AH39=0,"N/A",SUM(AH46/AH40+AH46/AH40*$C$32)) -> N/A
A48: Of which accrued interest | C48: =+IF(C39=0,"N/A",C46/C40*$C$32*C50) -> N/A | D48: =+IF(D39=0,"N/A",D46/D40*$C$32*D50) -> N/A | E48: =+IF(E39=0,"N/A",E46/E40*$C$32*E50) -> N/A | F48: =+IF(F39=0,"N/A",F46/F40*$C$32*F50) -> N/A | G48: =+IF(G39=0,"N/A",G46/G40*$C$32*G50) -> N/A | H48: =+IF(H39=0,"N/A",H46/H40*$C$32*H50) -> N/A | I48: =+IF(I39=0,"N/A",I46/I40*$C$32*I50) -> N/A | J48: =+IF(J39=0,"N/A",J46/J40*$C$32*J50) -> N/A | ... AH48: =+IF(AH39=0,"N/A",AH46/AH40*$C$32*AH50) -> N/A
A49: Month wages being paid | C49: =+Wages!$C$4 -> 1 | D49: =+Wages!$C$4 -> 1 | E49: =+Wages!$C$4 -> 1 | F49: =+Wages!$C$4 -> 1 | G49: =+Wages!$C$4 -> 1 | H49: =+Wages!$C$4 -> 1 | I49: =+Wages!$C$4 -> 1 | J49: =+Wages!$C$4 -> 1 | ... AH49: =+Wages!$C$4 -> 1
A50: Months repaid counter | C50: =IF(C39=0,0,IF(C49=C38,0,IF(SUM(C49-C38)>C40,C40,SUM(C49-C38)))) -> 0 | D50: =IF(D39=0,0,IF(D49=D38,0,IF(SUM(D49-D38)>D40,D40,SUM(D49-D38)))) -> 0 | E50: =IF(E39=0,0,IF(E49=E38,0,IF(SUM(E49-E38)>E40,E40,SUM(E49-E38)))) -> 0 | F50: =IF(F39=0,0,IF(F49=F38,0,IF(SUM(F49-F38)>F40,F40,SUM(F49-F38)))) -> 0 | G50: =IF(G39=0,0,IF(G49=G38,0,IF(SUM(G49-G38)>G40,G40,SUM(G49-G38)))) -> 0 | H50: =IF(H39=0,0,IF(H49=H38,0,IF(SUM(H49-H38)>H40,H40,SUM(H49-H38)))) -> 0 | I50: =IF(I39=0,0,IF(I49=I38,0,IF(SUM(I49-I38)>I40,I40,SUM(I49-I38)))) -> 0 | J50: =IF(J39=0,0,IF(J49=J38,0,IF(SUM(J49-J38)>J40,J40,SUM(J49-J38)))) -> 0 | ... AH50: =IF(AH39=0,0,IF(AH49=AH38,0,IF(SUM(AH49-AH38)>AH40,AH40,SUM(AH49-AH38)))) -> 0
A51: Months repaid | C51: =IF(C40=0,0,IF(OR(C50>C40,C50=C40),"Loan repaid",C50)) -> 0 | D51: =IF(D40=0,0,IF(OR(D50>D40,D50=D40),"Loan repaid",D50)) -> 0 | E51: =IF(E40=0,0,IF(OR(E50>E40,E50=E40),"Loan repaid",E50)) -> 0 | F51: =IF(F40=0,0,IF(OR(F50>F40,F50=F40),"Loan repaid",F50)) -> 0 | G51: =IF(G40=0,0,IF(OR(G50>G40,G50=G40),"Loan repaid",G50)) -> 0 | H51: =IF(H40=0,0,IF(OR(H50>H40,H50=H40),"Loan repaid",H50)) -> 0 | I51: =IF(I40=0,0,IF(OR(I50>I40,I50=I40),"Loan repaid",I50)) -> 0 | J51: =IF(J40=0,0,IF(OR(J50>J40,J50=J40),"Loan repaid",J50)) -> 0 | ... AH51: =IF(AH40=0,0,IF(OR(AH50>AH40,AH50=AH40),"Loan repaid",AH50)) -> 0
A52: Months remaining | C52: =IF(OR(C39=0,C38=0),"N/A",IF(C51="Loan repaid",0,IF(SUM(C40-C50)<0,0,SUM(C40-C51)))) -> N/A | D52: =IF(OR(D39=0,D38=0),"N/A",IF(D51="Loan repaid",0,IF(SUM(D40-D50)<0,0,SUM(D40-D51)))) -> N/A | E52: =IF(OR(E39=0,E38=0),"N/A",IF(E51="Loan repaid",0,IF(SUM(E40-E50)<0,0,SUM(E40-E51)))) -> N/A | F52: =IF(OR(F39=0,F38=0),"N/A",IF(F51="Loan repaid",0,IF(SUM(F40-F50)<0,0,SUM(F40-F51)))) -> N/A | G52: =IF(OR(G39=0,G38=0),"N/A",IF(G51="Loan repaid",0,IF(SUM(G40-G50)<0,0,SUM(G40-G51)))) -> N/A | H52: =IF(OR(H39=0,H38=0),"N/A",IF(H51="Loan repaid",0,IF(SUM(H40-H50)<0,0,SUM(H40-H51)))) -> N/A | I52: =IF(OR(I39=0,I38=0),"N/A",IF(I51="Loan repaid",0,IF(SUM(I40-I50)<0,0,SUM(I40-I51)))) -> N/A | J52: =IF(OR(J39=0,J38=0),"N/A",IF(J51="Loan repaid",0,IF(SUM(J40-J50)<0,0,SUM(J40-J51)))) -> N/A | ... AH52: =IF(OR(AH39=0,AH38=0),"N/A",IF(AH51="Loan repaid",0,IF(SUM(AH40-AH50)<0,0,SUM(AH40-AH51)))) -> N/A
A53: Amount repaid | C53: =IF(OR(C39=0,C38=0),0,IF(OR(C51="Loan repaid",(C50>C40)),SUM(C47*C40),SUM(C47*C51))) -> 0 | D53: =IF(OR(D39=0,D38=0),0,IF(OR(D51="Loan repaid",(D50>D40)),SUM(D47*D40),SUM(D47*D51))) -> 0 | E53: =IF(OR(E39=0,E38=0),0,IF(OR(E51="Loan repaid",(E50>E40)),SUM(E47*E40),SUM(E47*E51))) -> 0 | F53: =IF(OR(F39=0,F38=0),0,IF(OR(F51="Loan repaid",(F50>F40)),SUM(F47*F40),SUM(F47*F51))) -> 0 | G53: =IF(OR(G39=0,G38=0),0,IF(OR(G51="Loan repaid",(G50>G40)),SUM(G47*G40),SUM(G47*G51))) -> 0 | H53: =IF(OR(H39=0,H38=0),0,IF(OR(H51="Loan repaid",(H50>H40)),SUM(H47*H40),SUM(H47*H51))) -> 0 | I53: =IF(OR(I39=0,I38=0),0,IF(OR(I51="Loan repaid",(I50>I40)),SUM(I47*I40),SUM(I47*I51))) -> 0 | J53: =IF(OR(J39=0,J38=0),0,IF(OR(J51="Loan repaid",(J50>J40)),SUM(J47*J40),SUM(J47*J51))) -> 0 | ... AH53: =IF(OR(AH39=0,AH38=0),0,IF(OR(AH51="Loan repaid",(AH50>AH40)),SUM(AH47*AH40),SUM(AH47*AH51))) -> 0
A54: Outstanding amount | C54: =IF(OR(C39=0,C38=0,C52=0,C51="Loan repaid"),0,SUM(C46-C53)) -> 0 | D54: =IF(OR(D39=0,D38=0,D52=0,D51="Loan repaid"),0,SUM(D46-D53)) -> 0 | E54: =IF(OR(E39=0,E38=0,E52=0,E51="Loan repaid"),0,SUM(E46-E53)) -> 0 | F54: =IF(OR(F39=0,F38=0,F52=0,F51="Loan repaid"),0,SUM(F46-F53)) -> 0 | G54: =IF(OR(G39=0,G38=0,G52=0,G51="Loan repaid"),0,SUM(G46-G53)) -> 0 | H54: =IF(OR(H39=0,H38=0,H52=0,H51="Loan repaid"),0,SUM(H46-H53)) -> 0 | I54: =IF(OR(I39=0,I38=0,I52=0,I51="Loan repaid"),0,SUM(I46-I53)) -> 0 | J54: =IF(OR(J39=0,J38=0,J52=0,J51="Loan repaid"),0,SUM(J46-J53)) -> 0 | ... AH54: =IF(OR(AH39=0,AH38=0,AH52=0,AH51="Loan repaid"),0,SUM(AH46-AH53)) -> 0
A55: Deduction for the month | C55: =+IF(OR(C50=0,SUM(C49-C38)>C40),0,IF(SUM(C49-C38)=C40,C47,C47)) -> 0 | D55: =+IF(OR(D50=0,SUM(D49-D38)>D40),0,IF(SUM(D49-D38)=D40,D47,D47)) -> 0 | E55: =+IF(OR(E50=0,SUM(E49-E38)>E40),0,IF(SUM(E49-E38)=E40,E47,E47)) -> 0 | F55: =+IF(OR(F50=0,SUM(F49-F38)>F40),0,IF(SUM(F49-F38)=F40,F47,F47)) -> 0 | G55: =+IF(OR(G50=0,SUM(G49-G38)>G40),0,IF(SUM(G49-G38)=G40,G47,G47)) -> 0 | H55: =+IF(OR(H50=0,SUM(H49-H38)>H40),0,IF(SUM(H49-H38)=H40,H47,H47)) -> 0 | I55: =+IF(OR(I50=0,SUM(I49-I38)>I40),0,IF(SUM(I49-I38)=I40,I47,I47)) -> 0 | J55: =+IF(OR(J50=0,SUM(J49-J38)>J40),0,IF(SUM(J49-J38)=J40,J47,J47)) -> 0 | ... AH55: =+IF(OR(AH50=0,SUM(AH49-AH38)>AH40),0,IF(SUM(AH49-AH38)=AH40,AH47,AH47)) -> 0
A57: Calendar | D57: Concanation of Calendar Months and year
...

Sheet Combined Pay
B2: Citi-Nati Supermarket
A4: Wages for Residences, Supermarkets, Stop-Over and Restaurant
B6: Month for Payment of Wages: | C6: ='Res-Workers'!B81 -> Mid | D6: ='Res-Workers'!C81 -> January 2026
D9: Amount Due | E9: Loan Outstanding | F9: Accrued Interest
B10: Total Wages Due | D10: =D22+D49 -> 967000 | E10: =E22+E49 -> 0 | F10: =F22+F49 -> 0
A12: Count | B12: Nyambadwe and Domasi Residence
A13: 1 | B13: ='Res-Workers'!B68 -> Martin Kandalama | D13: ='Res-Workers'!G68 -> 35000 | E13: ='Res-Workers'!F68 -> 0 | F13: ='Res-Workers'!H68 -> 0
A14: =A13+1 -> 2 | B14: ='Res-Workers'!B69 -> Daniel Mponda | D14: ='Res-Workers'!G69 -> 35000 | E14: ='Res-Workers'!F69 -> 0 | F14: ='Res-Workers'!H69 -> 0
A15: =A14+1 -> 3 | B15: ='Res-Workers'!B70 -> Elizabeth Kabudula | D15: ='Res-Workers'!G70 -> 10000 | E15: ='Res-Workers'!F70 -> 0 | F15: ='Res-Workers'!H70 -> 0
A16: =A15+1 -> 4 | B16: ='Res-Workers'!B71 -> vacant | D16: ='Res-Workers'!G71 -> 0 | E16: ='Res-Workers'!F71 -> 0 | F16: ='Res-Workers'!H71 -> 0
A17: =A16+1 -> 5 | B17: ='Res-Workers'!B72 -> William Mahinya | D17: ='Res-Workers'!G72 -> 75000 | E17: ='Res-Workers'!F72 -> 0 | F17: ='Res-Workers'!H72 -> 0
A18: =A17+1 -> 6 | B18: ='Res-Workers'!B73 -> vacant | D18: ='Res-Workers'!G73 -> 0 | E18: ='Res-Workers'!F73 -> 0 | F18: ='Res-Workers'!H73 -> 0
A19: =A18+1 -> 7 | B19: ='Res-Workers'!B74 | D19: ='Res-Workers'!G74 -> 0 | E19: ='Res-Workers'!F74 -> 0 | F19: ='Res-Workers'!H74 -> 0
A20: =A19+1 -> 8 | B20: ='Res-Workers'!B75 -> vacant | D20: ='Res-Workers'!G75 -> 0 | E20: ='Res-Workers'!F75 -> 0 | F20: ='Res-Workers'!H75 -> 0
A21: =A20+1 -> 9 | B21: ='Res-Workers'!B76 -> Yankho Gulani | D21: ='Res-Workers'!G76 -> 60000 | E21: ='Res-Workers'!F76 -> 0 | F21: ='Res-Workers'!H76 -> 0
B22: Sub-Total | D22: =SUM(D13:D21) -> 215000 | E22: =SUM(E13:E21) -> 0 | F22: =SUM(F13:F21) -> 0
A24: Count | B24: Citi-Nati Supermarkets, Resturant and Stop Over
