Workbook

Sheet Sales Input
A1: Use This Sheet to Input Figures For Each Complete Month
A3: Month being reported upon | C3: January | D3: February | E3: March | F3: April | G3: May | H3: June | I3: July | J3: August | K3: September | L3: October | M3: November | N3: December | O3: Totals
A5: POS SALES REPORT
B6: Domasi POS end of Month | C6: 7458030 | D6: 0 | E6: 0 | F6: 0 | G6: 0 | H6: 0 | I6: 0 | J6: 0 | K6: 0 | L6: 0 | M6: 0 | N6: 0 | O6: =SUM(C6:N6) -> 7458030
B7: Chinyonga POS end of Month | C7: 0 | D7: 0 | E7: 0 | F7: 0 | G7: 0 | H7: 0 | I7: 0 | J7: 0 | K7: 0 | L7: 0 | M7: 0 | N7: 0 | O7: =SUM(C7:N7) -> 0
A9: CASH SALES REPORT
A10: 1 | B10: Domasi Supermarket | C10: 5014630 | D10: 0 | E10: 0 | F10: 0 | G10: 0 | H10: 0 | I10: 0 | J10: 4715460 | K10: 0 | L10: 0 | M10: 0 | N10: 0 | O10: =SUM(C10:N10) -> 9730090
A11: =A10+1 -> 2 | B11: Chinyonga Supermarket | C11: 0 | D11: 0 | E11: 0 | F11: 0 | G11: 0 | H11: 0 | I11: 0 | J11: 0 | K11: 0 | L11: 0 | M11: 0 | N11: 0 | O11: =SUM(C11:N11) -> 0
A12: =A11+1 -> 3 | B12: Stop Over | C12: 1354050 | D12: 0 | E12: 0 | F12: 0 | G12: 0 | H12: 0 | I12: 0 | J12: 3303950 | K12: 0 | L12: 0 | M12: 0 | N12: 0 | O12: =SUM(C12:N12) -> 4658000
A13: =A12+1 -> 4 | B13: Nati-Foods | C13: 0 | D13: 0 | E13: 0 | F13: 0 | G13: 0 | H13: 0 | I13: 0 | J13: 0 | K13: 0 | L13: 0 | M13: 0 | N13: 0 | O13: =SUM(C13:N13) -> 0
A14: =A13+1 -> 5 | B14: Braai | C14: 75200 | D14: 0 | E14: 0 | F14: 0 | G14: 0 | H14: 0 | I14: 0 | J14: 120000 | K14: 0 | L14: 0 | M14: 0 | N14: 0 | O14: =SUM(C14:N14) -> 195200
A15: =A14+1 -> 6 | B15: Pool Table | C15: 102500 | D15: 0 | E15: 0 | F15: 0 | G15: 0 | H15: 0 | I15: 0 | J15: 236500 | K15: 0 | L15: 0 | M15: 0 | N15: 0 | O15: =SUM(C15:N15) -> 339000
A16: =A15+1 -> 7 | B16: AirTime | C16: 0 | D16: 0 | E16: 0 | F16: 0 | G16: 0 | H16: 0 | I16: 0 | J16: 0 | K16: 0 | L16: 0 | M16: 0 | N16: 0 | O16: =SUM(C16:N16) -> 0
A17: =A16+1 -> 8 | B17: Student Accommodation | C17: 0 | D17: 0 | E17: 0 | F17: 0 | G17: 0 | H17: 0 | I17: 0 | J17: 460000 | K17: 0 | L17: 0 | M17: 0 | N17: 0 | O17: =SUM(C17:N17) -> 460000
A19: SALES THRU GADGETS REPORT
A20: 1 | B20: Domasi Supermarket
B21: a. Airtel Money | C21: 412090 | D21: 0 | E21: 0 | F21: 0 | G21: 0 | H21: 0 | I21: 0 | J21: 784650 | K21: 0 | L21: 0 | M21: 0 | N21: 0 | O21: =SUM(C21:N21) -> 1196740
B22: b. MO626 | C22: 0 | D22: 0 | E22: 0 | F22: 0 | G22: 0 | H22: 0 | I22: 0 | J22: 205650 | K22: 0 | L22: 0 | M22: 0 | N22: 0 | O22: =SUM(C22:N22) -> 205650
B23: c. TNM Mpamba | C23: 0 | D23: 0 | E23: 0 | F23: 0 | G23: 0 | H23: 0 | I23: 0 | J23: 74900 | K23: 0 | L23: 0 | M23: 0 | N23: 0 | O23: =SUM(C23:N23) -> 74900
B24: d. FDH Bank | C24: 0 | D24: 0 | E24: 0 | F24: 0 | G24: 0 | H24: 0 | I24: 0 | J24: 0 | K24: 0 | L24: 0 | M24: 0 | N24: 0 | O24: =SUM(C24:N24) -> 0
A25: 1 | B25: Chinyonga Supermarket
B26: a. Airtel Money | C26: 0 | D26: 0 | E26: 0 | F26: 0 | G26: 0 | H26: 0 | I26: 0 | J26: 0 | K26: 0 | L26: 0 | M26: 0 | N26: 0 | O26: =SUM(C26:N26) -> 0
B27: b. MO626 | C27: 0 | D27: 0 | E27: 0 | F27: 0 | G27: 0 | H27: 0 | I27: 0 | J27: 0 | K27: 0 | L27: 0 | M27: 0 | N27: 0 | O27: =SUM(C27:N27) -> 0
B28: c. TNM Mpamba | C28: 0 | D28: 0 | E28: 0 | F28: 0 | G28: 0 | H28: 0 | I28: 0 | J28: 0 | K28: 0 | L28: 0 | M28: 0 | N28: 0 | O28: =SUM(C28:N28) -> 0
B29: d. FDH Bank | C29: 0 | D29: 0 | E29: 0 | F29: 0 | G29: 0 | H29: 0 | I29: 0 | J29: 0 | K29: 0 | L29: 0 | M29: 0 | N29: 0 | O29: =SUM(C29:N29) -> 0
A30: 2 | B30: Stop Over
B31: a. Airtel Money | C31: 600550 | D31: 0 | E31: 0 | F31: 0 | G31: 0 | H31: 0 | I31: 0 | J31: 1526450 | K31: 0 | L31: 0 | M31: 0 | N31: 0 | O31: =SUM(C31:N31) -> 2127000
B32: b. MO626 | C32: 0 | D32: 0 | E32: 0 | F32: 0 | G32: 0 | H32: 0 | I32: 0 | J32: 566700 | K32: 0 | L32: 0 | M32: 0 | N32: 0 | O32: =SUM(C32:N32) -> 566700
B33: c. TNM Mpamba | C33: 0 | D33: 0 | E33: 0 | F33: 0 | G33: 0 | H33: 0 | I33: 0 | J33: 223700 | K33: 0 | L33: 0 | M33: 0 | N33: 0 | O33: =SUM(C33:N33) -> 223700
B34: d. FDH Bank | C34: 0 | D34: 0 | E34: 0 | F34: 0 | G34: 0 | H34: 0 | I34: 0 | J34: 0 | K34: 0 | L34: 0 | M34: 0 | N34: 0 | O34: =SUM(C34:N34) -> 0
A35: 3 | B35: Nati-Foods
B36: a. Airtel Money | C36: 0 | D36: 0 | E36: 0 | F36: 0 | G36: 0 | H36: 0 | I36: 0 | J36: 0 | K36: 0 | L36: 0 | M36: 0 | N36: 0 | O36: =SUM(C36:N36) -> 0
B37: b. MO626 | C37: 0 | D37: 0 | E37: 0 | F37: 0 | G37: 0 | H37: 0 | I37: 0 | J37: 0 | K37: 0 | L37: 0 | M37: 0 | N37: 0 | O37: =SUM(C37:N37) -> 0
B38: c. TNM Mpamba | C38: 0 | D38: 0 | E38: 0 | F38: 0 | G38: 0 | H38: 0 | I38: 0 | J38: 0 | K38: 0 | L38: 0 | M38: 0 | N38: 0 | O38: =SUM(C38:N38) -> 0
B39: d. FDH Bank | C39: 0 | D39: 0 | E39: 0 | F39: 0 | G39: 0 | H39: 0 | I39: 0 | J39: 0 | K39: 0 | L39: 0 | M39: 0 | N39: 0 | O39: =SUM(C39:N39) -> 0
A40: 4 | B40: Braai
B41: a. Airtel Money | C41: 0 | D41: 0 | E41: 0 | F41: 0 | G41: 0 | H41: 0 | I41: 0 | J41: 0 | K41: 0 | L41: 0 | M41: 0 | N41: 0 | O41: =SUM(C41:N41) -> 0
B42: b. MO626 | C42: 0 | D42: 0 | E42: 0 | F42: 0 | G42: 0 | H42: 0 | I42: 0 | J42: 0 | K42: 0 | L42: 0 | M42: 0 | N42: 0 | O42: =SUM(C42:N42) -> 0
B43: c. TNM Mpamba | C43: 0 | D43: 0 | E43: 0 | F43: 0 | G43: 0 | H43: 0 | I43: 0 | J43: 0 | K43: 0 | L43: 0 | M43: 0 | N43: 0 | O43: =SUM(C43:N43) -> 0
B44: d. FDH Bank | C44: 0 | D44: 0 | E44: 0 | F44: 0 | G44: 0 | H44: 0 | I44: 0 | J44: 0 | K44: 0 | L44: 0 | M44: 0 | N44: 0 | O44: =SUM(C44:N44) -> 0
...

Sheet Consolidated Sales
A1: Sales Report for Supermarket, Stop-Over and Restaurant
B2: Month of Report | C2: =Summary!C3 -> 8
B4: Sales as at | C4: =IF($C$2=1,I6,IF($C$2=2,I7,IF($C$2=3,I8,IF($C$2=4,I9,IF($C$2=5,I11,IF($C$2=6,I12,IF($C$2=7,I13,IF($C$2=8,I14,IF($C$2=9,I15,IF($C$2=10,I16,IF($C$2=11,I17,IF($C$2=12,I18,IF($C$2=13,"Cummulative Totals","Enter correct month"))))))))))))) -> August 2025 | F4: Calendar | I4: Concanation of Calendar Months and year
F5: December | G5: 2024 | I5: =CONCATENATE(F5,G5) -> December 2024
F6: January | G6: =+G5+1 -> 2025 | I6: =CONCATENATE(F6,G6) -> January 2025
C7: Amount Paid | D7: Outstanding Amount | F7: February | G7: =+G6 -> 2025 | I7: =CONCATENATE(F7,G7) -> February 2025
A8: CASH SALES REPORT | F8: March | G8: =+G7 -> 2025 | I8: =CONCATENATE(F8,G8) -> March 2025
A9: 1 | B9: ='Sales Input'!B10 -> Domasi Supermarket | C9: =IF($C$2=1,'Sales Input'!C10,IF($C$2=2,'Sales Input'!D10,IF($C$2=3,'Sales Input'!E10,IF($C$2=4,'Sales Input'!F10,IF($C$2=5,'Sales Input'!G10,IF($C$2=6,'Sales Input'!H10,IF($C$2=7,'Sales Input'!I10,IF($C$2=8,'Sales Input'!J10,IF($C$2=9,'Sales Input'!K10,IF($C$2=10,'Sales Input'!L10,IF($C$2=11,'Sales Input'!M10,IF($C$2=12,'Sales Input'!N10,IF($C$2=13,'Sales Input'!O10,0))))))))))))) -> 4715460 | F9: April | G9: =+G8 -> 2025 | I9: =CONCATENATE(F9,G9) -> April 2025
A10: =A9+1 -> 2 | B10: ='Sales Input'!B11 -> Chinyonga Supermarket | C10: =IF($C$2=1,'Sales Input'!C11,IF($C$2=2,'Sales Input'!D11,IF($C$2=3,'Sales Input'!E11,IF($C$2=4,'Sales Input'!F11,IF($C$2=5,'Sales Input'!G11,IF($C$2=6,'Sales Input'!H11,IF($C$2=7,'Sales Input'!I11,IF($C$2=8,'Sales Input'!J11,IF('Consolidated Sales'!$C$2=9,'Sales Input'!K11,IF($C$2=10,'Sales Input'!L11,IF($C$2=11,'Sales Input'!M11,IF($C$2=12,'Sales Input'!N11,IF($C$2=13,'Sales Input'!O11,0))))))))))))) -> 0
A11: =A10+1 -> 3 | B11: Stop Over | C11: =IF($C$2=1,'Sales Input'!C12,IF($C$2=2,'Sales Input'!D12,IF($C$2=3,'Sales Input'!E12,IF($C$2=4,'Sales Input'!F12,IF($C$2=5,'Sales Input'!G12,IF($C$2=6,'Sales Input'!H12,IF($C$2=7,'Sales Input'!I12,IF($C$2=8,'Sales Input'!J12,IF($C$2=9,'Sales Input'!K12,IF($C$2=10,'Sales Input'!L12,IF($C$2=11,'Sales Input'!M12,IF($C$2=12,'Sales Input'!N12,IF($C$2=13,'Sales Input'!O12,0))))))))))))) -> 3303950 | F11: May | G11: =+G9 -> 2025 | I11: =CONCATENATE(F11,G11) -> May 2025
A12: =A11+1 -> 4 | B12: Nati-Foods | C12: =IF($C$2=1,'Sales Input'!C13,IF($C$2=2,'Sales Input'!D13,IF($C$2=3,'Sales Input'!E13,IF($C$2=4,'Sales Input'!F13,IF($C$2=5,'Sales Input'!G13,IF($C$2=6,'Sales Input'!H13,IF($C$2=7,'Sales Input'!I13,IF($C$2=8,'Sales Input'!J13,IF($C$2=9,'Sales Input'!K13,IF($C$2=10,'Sales Input'!L13,IF($C$2=11,'Sales Input'!M13,IF($C$2=12,'Sales Input'!N13,IF($C$2=13,'Sales Input'!O13,0))))))))))))) -> 0 | F12: June | G12: =+G11 -> 2025 | I12: =CONCATENATE(F12,G12) -> June 2025
A13: =A12+1 -> 5 | B13: Braai | C13: =IF($C$2=1,'Sales Input'!C14,IF($C$2=2,'Sales Input'!D14,IF($C$2=3,'Sales Input'!E14,IF($C$2=4,'Sales Input'!F14,IF($C$2=5,'Sales Input'!G14,IF($C$2=6,'Sales Input'!H14,IF($C$2=7,'Sales Input'!I14,IF($C$2=8,'Sales Input'!J14,IF($C$2=9,'Sales Input'!K14,IF($C$2=10,'Sales Input'!L14,IF($C$2=11,'Sales Input'!M14,IF($C$2=12,'Sales Input'!N14,IF($C$2=13,'Sales Input'!O14,0))))))))))))) -> 120000 | F13: July | G13: =+G12 -> 2025 | I13: =CONCATENATE(F13,G13) -> July 2025
A14: =A13+1 -> 6 | B14: Pool Table | C14: =IF($C$2=1,'Sales Input'!C15,IF($C$2=2,'Sales Input'!D15,IF($C$2=3,'Sales Input'!E15,IF($C$2=4,'Sales Input'!F15,IF($C$2=5,'Sales Input'!G15,IF($C$2=6,'Sales Input'!H15,IF($C$2=7,'Sales Input'!I15,IF($C$2=8,'Sales Input'!J15,IF($C$2=9,'Sales Input'!K15,IF($C$2=10,'Sales Input'!L15,IF($C$2=11,'Sales Input'!M15,IF($C$2=12,'Sales Input'!N15,IF($C$2=13,'Sales Input'!O15,0))))))))))))) -> 236500 | F14: August | G14: =+G13 -> 2025 | I14: =CONCATENATE(F14,G14) -> August 2025
A15: =A14+1 -> 7 | B15: AirTime | C15: =IF($C$2=1,'Sales Input'!C16,IF($C$2=2,'Sales Input'!D16,IF($C$2=3,'Sales Input'!E16,IF($C$2=4,'Sales Input'!F16,IF($C$2=5,'Sales Input'!G16,IF($C$2=6,'Sales Input'!H16,IF($C$2=7,'Sales Input'!I16,IF($C$2=8,'Sales Input'!J16,IF($C$2=9,'Sales Input'!K16,IF($C$2=10,'Sales Input'!L16,IF($C$2=11,'Sales Input'!M16,IF($C$2=12,'Sales Input'!N16,IF($C$2=13,'Sales Input'!O16,0))))))))))))) -> 0 | F15: September | G15: =+G14 -> 2025 | I15: =CONCATENATE(F15,G15) -> September 2025
A16: =A15+1 -> 8 | B16: Student Accommodation | C16: =IF($C$2=1,'Sales Input'!C17,IF($C$2=2,'Sales Input'!D17,IF($C$2=3,'Sales Input'!E17,IF($C$2=4,'Sales Input'!F17,IF($C$2=5,'Sales Input'!G17,IF($C$2=6,'Sales Input'!H17,IF($C$2=7,'Sales Input'!I17,IF($C$2=8,'Sales Input'!J17,IF($C$2=9,'Sales Input'!K17,IF($C$2=10,'Sales Input'!L17,IF($C$2=11,'Sales Input'!M17,IF($C$2=12,'Sales Input'!N17,IF($C$2=13,'Sales Input'!O17,0))))))))))))) -> 460000 | F16: October | G16: =+G15 -> 2025 | I16: =CONCATENATE(F16,G16) -> October 2025
B17: Total Cash in Hand | C17: =SUM(C9:C16) -> 8835910 | F17: November | G17: =+G16 -> 2025 | I17: =CONCATENATE(F17,G17) -> November 2025
F18: December | G18: =+G17 -> 2025 | I18: =CONCATENATE(F18,G18) -> December 2025
A19: SALES THRU GADGETS REPORT | G19: =G6+1 -> 2026
A20: 1 | B20: ='Sales Input'!B20 -> Domasi Supermarket
B21: a. Airtel Money | C21: =IF($C$2=1,'Sales Input'!C21,IF($C$2=2,'Sales Input'!D21,IF($C$2=3,'Sales Input'!E21,IF($C$2=4,'Sales Input'!F21,IF($C$2=5,'Sales Input'!G21,IF($C$2=6,'Sales Input'!H21,IF($C$2=7,'Sales Input'!I21,IF($C$2=8,'Sales Input'!J21,IF($C$2=9,'Sales Input'!K21,IF($C$2=10,'Sales Input'!L21,IF($C$2=11,'Sales Input'!M21,IF($C$2=12,'Sales Input'!N21,IF($C$2=13,'Sales Input'!O21,0))))))))))))) -> 784650
B22: b. MO626 | C22: =IF($C$2=1,'Sales Input'!C22,IF($C$2=2,'Sales Input'!D22,IF($C$2=3,'Sales Input'!E22,IF($C$2=4,'Sales Input'!F22,IF($C$2=5,'Sales Input'!G22,IF($C$2=6,'Sales Input'!H22,IF($C$2=7,'Sales Input'!I22,IF($C$2=8,'Sales Input'!J22,IF($C$2=9,'Sales Input'!K22,IF($C$2=10,'Sales Input'!L22,IF($C$2=11,'Sales Input'!M22,IF($C$2=12,'Sales Input'!N22,IF($C$2=13,'Sales Input'!O22,0))))))))))))) -> 205650 | G22: password | H22: wag3s
B23: c. TNM Mpamba | C23: =IF($C$2=1,'Sales Input'!C23,IF($C$2=2,'Sales Input'!D23,IF($C$2=3,'Sales Input'!E23,IF($C$2=4,'Sales Input'!F23,IF($C$2=5,'Sales Input'!G23,IF($C$2=6,'Sales Input'!H23,IF($C$2=7,'Sales Input'!I23,IF($C$2=8,'Sales Input'!J23,IF($C$2=9,'Sales Input'!K23,IF($C$2=10,'Sales Input'!L23,IF($C$2=11,'Sales Input'!M23,IF($C$2=12,'Sales Input'!N23,IF($C$2=13,'Sales Input'!O23,0))))))))))))) -> 74900
B24: d. FDH Bank | C24: =IF($C$2=1,'Sales Input'!C24,IF($C$2=2,'Sales Input'!D24,IF($C$2=3,'Sales Input'!E24,IF($C$2=4,'Sales Input'!F24,IF($C$2=5,'Sales Input'!G24,IF($C$2=6,'Sales Input'!H24,IF($C$2=7,'Sales Input'!I24,IF($C$2=8,'Sales Input'!J24,IF($C$2=9,'Sales Input'!K24,IF($C$2=10,'Sales Input'!L24,IF($C$2=11,'Sales Input'!M24,IF($C$2=12,'Sales Input'!N24,IF($C$2=13,'Sales Input'!O24,0))))))))))))) -> 0
B25: Sub-Total | C25: =SUM(C21:C24) -> 1065200
A26: 2 | B26: ='Sales Input'!B25 -> Chinyonga Supermarket
B27: a. Airtel Money | C27: =IF($C$2=1,'Sales Input'!C26,IF($C$2=2,'Sales Input'!D26,IF($C$2=3,'Sales Input'!E26,IF($C$2=4,'Sales Input'!F26,IF($C$2=5,'Sales Input'!G26,IF($C$2=6,'Sales Input'!H26,IF($C$2=7,'Sales Input'!I26,IF($C$2=8,'Sales Input'!J26,IF($C$2=9,'Sales Input'!K26,IF($C$2=10,'Sales Input'!L26,IF($C$2=11,'Sales Input'!M26,IF($C$2=12,'Sales Input'!N26,IF($C$2=13,'Sales Input'!O26,0))))))))))))) -> 0
B28: b. MO626 | C28: =IF($C$2=1,'Sales Input'!C27,IF($C$2=2,'Sales Input'!D27,IF($C$2=3,'Sales Input'!E27,IF($C$2=4,'Sales Input'!F27,IF($C$2=5,'Sales Input'!G27,IF($C$2=6,'Sales Input'!H27,IF($C$2=7,'Sales Input'!I27,IF($C$2=8,'Sales Input'!J27,IF($C$2=9,'Sales Input'!K27,IF($C$2=10,'Sales Input'!L27,IF($C$2=11,'Sales Input'!M27,IF($C$2=12,'Sales Input'!N27,IF($C$2=13,'Sales Input'!O27,0))))))))))))) -> 0
B29: c. TNM Mpamba | C29: =IF($C$2=1,'Sales Input'!C28,IF($C$2=2,'Sales Input'!D28,IF($C$2=3,'Sales Input'!E28,IF($C$2=4,'Sales Input'!F28,IF($C$2=5,'Sales Input'!G28,IF($C$2=6,'Sales Input'!H28,IF($C$2=7,'Sales Input'!I28,IF($C$2=8,'Sales Input'!J28,IF($C$2=9,'Sales Input'!K28,IF($C$2=10,'Sales Input'!L28,IF($C$2=11,'Sales Input'!M28,IF($C$2=12,'Sales Input'!N28,IF($C$2=13,'Sales Input'!O28,0))))))))))))) -> 0
B30: d. FDH Bank | C30: =IF($C$2=1,'Sales Input'!C29,IF($C$2=2,'Sales Input'!D29,IF($C$2=3,'Sales Input'!E29,IF($C$2=4,'Sales Input'!F29,IF($C$2=5,'Sales Input'!G29,IF($C$2=6,'Sales Input'!H29,IF($C$2=7,'Sales Input'!I29,IF($C$2=8,'Sales Input'!J29,IF($C$2=9,'Sales Input'!K29,IF($C$2=10,'Sales Input'!L29,IF($C$2=11,'Sales Input'!M29,IF($C$2=12,'Sales Input'!N29,IF($C$2=13,'Sales Input'!O29,0))))))))))))) -> 0
B31: Sub-Total | C31: =SUM(C27:C30) -> 0
A32: 3 | B32: Stop Over
B33: a. Airtel Money | C33: =IF($C$2=1,'Sales Input'!C31,IF($C$2=2,'Sales Input'!D31,IF($C$2=3,'Sales Input'!E31,IF($C$2=4,'Sales Input'!F31,IF($C$2=5,'Sales Input'!G31,IF($C$2=6,'Sales Input'!H31,IF($C$2=7,'Sales Input'!I31,IF($C$2=8,'Sales Input'!J31,IF($C$2=9,'Sales Input'!K31,IF($C$2=10,'Sales Input'!L31,IF($C$2=11,'Sales Input'!M31,IF($C$2=12,'Sales Input'!N31,IF($C$2=13,'Sales Input'!O31,0))))))))))))) -> 1526450
B34: b. MO626 | C34: =IF($C$2=1,'Sales Input'!C32,IF($C$2=2,'Sales Input'!D32,IF($C$2=3,'Sales Input'!E32,IF($C$2=4,'Sales Input'!F32,IF($C$2=5,'Sales Input'!G32,IF($C$2=6,'Sales Input'!H32,IF($C$2=7,'Sales Input'!I32,IF($C$2=8,'Sales Input'!J32,IF($C$2=9,'Sales Input'!K32,IF($C$2=10,'Sales Input'!L32,IF($C$2=11,'Sales Input'!M32,IF($C$2=12,'Sales Input'!N32,IF($C$2=13,'Sales Input'!O32,0))))))))))))) -> 566700
B35: c. TNM Mpamba | C35: =IF($C$2=1,'Sales Input'!C33,IF($C$2=2,'Sales Input'!D33,IF($C$2=3,'Sales Input'!E33,IF($C$2=4,'Sales Input'!F33,IF($C$2=5,'Sales Input'!G33,IF($C$2=6,'Sales Input'!H33,IF($C$2=7,'Sales Input'!I33,IF($C$2=8,'Sales Input'!J33,IF($C$2=9,'Sales Input'!K33,IF($C$2=10,'Sales Input'!L33,IF($C$2=11,'Sales Input'!M33,IF($C$2=12,'Sales Input'!N33,IF($C$2=13,'Sales Input'!O33,0))))))))))))) -> 223700
B36: d. FDH Bank | C36: =IF($C$2=1,'Sales Input'!C34,IF($C$2=2,'Sales Input'!D34,IF($C$2=3,'Sales Input'!E34,IF($C$2=4,'Sales Input'!F34,IF($C$2=5,'Sales Input'!G34,IF($C$2=6,'Sales Input'!H34,IF($C$2=7,'Sales Input'!I34,IF($C$2=8,'Sales Input'!J34,IF($C$2=9,'Sales Input'!K34,IF($C$2=10,'Sales Input'!L34,IF($C$2=11,'Sales Input'!M34,IF($C$2=12,'Sales Input'!N34,IF($C$2=13,'Sales Input'!O34,0))))))))))))) -> 0
B37: Sub-Total | C37: =SUM(C33:C36) -> 2316850
A38: 4 | B38: Nati-Foods
B39: a. Airtel Money | C39: =IF($C$2=1,'Sales Input'!C36,IF($C$2=2,'Sales Input'!D36,IF($C$2=3,'Sales Input'!E36,IF($C$2=4,'Sales Input'!F36,IF($C$2=5,'Sales Input'!G36,IF($C$2=6,'Sales Input'!H36,IF($C$2=7,'Sales Input'!I36,IF($C$2=8,'Sales Input'!J36,IF($C$2=9,'Sales Input'!K36,IF($C$2=10,'Sales Input'!L36,IF($C$2=11,'Sales Input'!M36,IF($C$2=12,'Sales Input'!N36,IF($C$2=13,'Sales Input'!O36,0))))))))))))) -> 0
B40: b. MO626 | C40: =IF($C$2=1,'Sales Input'!C37,IF($C$2=2,'Sales Input'!D37,IF($C$2=3,'Sales Input'!E37,IF($C$2=4,'Sales Input'!F37,IF($C$2=5,'Sales Input'!G37,IF($C$2=6,'Sales Input'!H37,IF($C$2=7,'Sales Input'!I37,IF($C$2=8,'Sales Input'!J37,IF($C$2=9,'Sales Input'!K37,IF($C$2=10,'Sales Input'!L37,IF($C$2=11,'Sales Input'!M37,IF($C$2=12,'Sales Input'!N37,IF($C$2=13,'Sales Input'!O37,0))))))))))))) -> 0
B41: c. TNM Mpamba | C41: =IF($C$2=1,'Sales Input'!C38,IF($C$2=2,'Sales Input'!D38,IF($C$2=3,'Sales Input'!E38,IF($C$2=4,'Sales Input'!F38,IF($C$2=5,'Sales Input'!G38,IF($C$2=6,'Sales Input'!H38,IF($C$2=7,'Sales Input'!I38,IF($C$2=8,'Sales Input'!J38,IF($C$2=9,'Sales Input'!K38,IF($C$2=10,'Sales Input'!L38,IF($C$2=11,'Sales Input'!M38,IF($C$2=12,'Sales Input'!N38,IF($C$2=13,'Sales Input'!O38,0))))))))))))) -> 0 | E41: `
...

Sheet Suppliers Report
A1: GOODS SUPPLIED REPORT
C4: Amount Due to Suppliers | E4: Payments by Cash-in-Hand | G4: Payments by Bank Transfer | I4: Payments by Wallet | K4: Payments by Capital Injection
B5: Supplier Name | C5: Debt Amount | D5: Outstanding Amount | E5: Amount Paid | F5: Outstanding Amount | G5: Amount Paid | H5: Outstanding Amount | I5: Amount Paid | J5: Outstanding Amount | K5: Amount Paid | L5: Outstanding Amount
B6: Universal Industries | C6: =IF('Consolidated Sales'!$C$2=1,'Sales Input'!C69,IF('Consolidated Sales'!$C$2=2,'Sales Input'!D69,IF('Consolidated Sales'!$C$2=3,'Sales Input'!E69,IF('Consolidated Sales'!$C$2=4,'Sales Input'!F69,IF('Consolidated Sales'!$C$2=5,'Sales Input'!G69,IF('Consolidated Sales'!$C$2=6,'Sales Input'!H69,IF('Consolidated Sales'!$C$2=7,'Sales Input'!I69,IF('Consolidated Sales'!$C$2=8,'Sales Input'!J69,IF('Consolidated Sales'!$C$2=9,'Sales Input'!K69,IF('Consolidated Sales'!$C$2=10,'Sales Input'!L69,IF('Consolidated Sales'!$C$2=11,'Sales Input'!M69,IF('Consolidated Sales'!$C$2=12,'Sales Input'!N69,IF('Consolidated Sales'!$C$2=13,'Sales Input'!O69,0))))))))))))) -> 323500.02 | D6: =SUM(C6-E6-G6-I6-K6) -> 0 | E6: =IF('Consolidated Sales'!$C$2=1,'Sales Input'!C103,IF('Consolidated Sales'!$C$2=2,'Sales Input'!D103,IF('Consolidated Sales'!$C$2=3,'Sales Input'!E103,IF('Consolidated Sales'!$C$2=4,'Sales Input'!F103,IF('Consolidated Sales'!$C$2=5,'Sales Input'!G103,IF('Consolidated Sales'!$C$2=6,'Sales Input'!H103,IF('Consolidated Sales'!$C$2=7,'Sales Input'!I103,IF('Consolidated Sales'!$C$2=8,'Sales Input'!J103,IF('Consolidated Sales'!$C$2=9,'Sales Input'!K103,IF('Consolidated Sales'!$C$2=10,'Sales Input'!L103,IF('Consolidated Sales'!$C$2=11,'Sales Input'!M103,IF('Consolidated Sales'!$C$2=12,'Sales Input'!N103,IF('Consolidated Sales'!$C$2=13,'Sales Input'!O103,0))))))))))))) -> 0 | F6: =SUM(C6-E6-G6-I6-K6) -> 0 | G6: =IF('Consolidated Sales'!$C$2=1,'Sales Input'!C125,IF('Consolidated Sales'!$C$2=2,'Sales Input'!D125,IF('Consolidated Sales'!$C$2=3,'Sales Input'!E125,IF('Consolidated Sales'!$C$2=4,'Sales Input'!F125,IF('Consolidated Sales'!$C$2=5,'Sales Input'!G125,IF('Consolidated Sales'!$C$2=6,'Sales Input'!H125,IF('Consolidated Sales'!$C$2=7,'Sales Input'!I125,IF('Consolidated Sales'!$C$2=8,'Sales Input'!J125,IF('Consolidated Sales'!$C$2=9,'Sales Input'!K125,IF('Consolidated Sales'!$C$2=10,'Sales Input'!L125,IF('Consolidated Sales'!$C$2=11,'Sales Input'!M125,IF('Consolidated Sales'!$C$2=12,'Sales Input'!N125,IF('Consolidated Sales'!$C$2=13,'Sales Input'!O125,0))))))))))))) -> 323500.02 | H6: =C6-E6-G6-I6-K6 -> 0 | I6: =IF('Consolidated Sales'!$C$2=1,'Sales Input'!C147,IF('Consolidated Sales'!$C$2=2,'Sales Input'!D147,IF('Consolidated Sales'!$C$2=3,'Sales Input'!E147,IF('Consolidated Sales'!$C$2=4,'Sales Input'!F147,IF('Consolidated Sales'!$C$2=5,'Sales Input'!G147,IF('Consolidated Sales'!$C$2=6,'Sales Input'!H147,IF('Consolidated Sales'!$C$2=7,'Sales Input'!I147,IF('Consolidated Sales'!$C$2=8,'Sales Input'!J147,IF('Consolidated Sales'!$C$2=9,'Sales Input'!K147,IF('Consolidated Sales'!$C$2=10,'Sales Input'!L147,IF('Consolidated Sales'!$C$2=11,'Sales Input'!M147,IF('Consolidated Sales'!$C$2=12,'Sales Input'!N147,IF('Consolidated Sales'!$C$2=13,'Sales Input'!O147,0))))))))))))) -> 0 | J6: =C6-E6-G6-I6-K6 -> 0 | K6: =IF('Consolidated Sales'!$C$2=1,'Sales Input'!C169,IF('Consolidated Sales'!$C$2=2,'Sales Input'!D169,IF('Consolidated Sales'!$C$2=3,'Sales Input'!E169,IF('Consolidated Sales'!$C$2=4,'Sales Input'!F169,IF('Consolidated Sales'!$C$2=5,'Sales Input'!G169,IF('Consolidated Sales'!$C$2=6,'Sales Input'!H169,IF('Consolidated Sales'!$C$2=7,'Sales Input'!I169,IF('Consolidated Sales'!$C$2=8,'Sales Input'!J169,IF('Consolidated Sales'!$C$2=9,'Sales Input'!K169,IF('Consolidated Sales'!$C$2=10,'Sales Input'!L169,IF('Consolidated Sales'!$C$2=11,'Sales Input'!M169,IF('Consolidated Sales'!$C$2=12,'Sales Input'!N169,IF('Consolidated Sales'!$C$2=13,'Sales Input'!O169,0))))))))))))) -> 0 | L6: =C6-E6-G6-I6-K6 -> 0
B7: Bottled Water | C7: =IF('Consolidated Sales'!$C$2=1,'Sales Input'!C70,IF('Consolidated Sales'!$C$2=2,'Sales Input'!D70,IF('Consolidated Sales'!$C$2=3,'Sales Input'!E70,IF('Consolidated Sales'!$C$2=4,'Sales Input'!F70,IF('Consolidated Sales'!$C$2=5,'Sales Input'!G70,IF('Consolidated Sales'!$C$2=6,'Sales Input'!H70,IF('Consolidated Sales'!$C$2=7,'Sales Input'!I70,IF('Consolidated Sales'!$C$2=8,'Sales Input'!J70,IF('Consolidated Sales'!$C$2=9,'Sales Input'!K70,IF('Consolidated Sales'!$C$2=10,'Sales Input'!L70,IF('Consolidated Sales'!$C$2=11,'Sales Input'!M70,IF('Consolidated Sales'!$C$2=12,'Sales Input'!N70,IF('Consolidated Sales'!$C$2=13,'Sales Input'!O70,0))))))))))))) -> 0 | D7: =SUM(C7-E7-G7-I7-K7) -> 0 | E7: =IF('Consolidated Sales'!$C$2=1,'Sales Input'!C104,IF('Consolidated Sales'!$C$2=2,'Sales Input'!D104,IF('Consolidated Sales'!$C$2=3,'Sales Input'!E104,IF('Consolidated Sales'!$C$2=4,'Sales Input'!F104,IF('Consolidated Sales'!$C$2=5,'Sales Input'!G104,IF('Consolidated Sales'!$C$2=6,'Sales Input'!H104,IF('Consolidated Sales'!$C$2=7,'Sales Input'!I104,IF('Consolidated Sales'!$C$2=8,'Sales Input'!J104,IF('Consolidated Sales'!$C$2=9,'Sales Input'!K104,IF('Consolidated Sales'!$C$2=10,'Sales Input'!L104,IF('Consolidated Sales'!$C$2=11,'Sales Input'!M104,IF('Consolidated Sales'!$C$2=12,'Sales Input'!N104,IF('Consolidated Sales'!$C$2=13,'Sales Input'!O104,0))))))))))))) -> 0 | F7: =SUM(C7-E7-G7-I7-K7) -> 0 | G7: =IF('Consolidated Sales'!$C$2=1,'Sales Input'!C126,IF('Consolidated Sales'!$C$2=2,'Sales Input'!D126,IF('Consolidated Sales'!$C$2=3,'Sales Input'!E126,IF('Consolidated Sales'!$C$2=4,'Sales Input'!F126,IF('Consolidated Sales'!$C$2=5,'Sales Input'!G126,IF('Consolidated Sales'!$C$2=6,'Sales Input'!H126,IF('Consolidated Sales'!$C$2=7,'Sales Input'!I126,IF('Consolidated Sales'!$C$2=8,'Sales Input'!J126,IF('Consolidated Sales'!$C$2=9,'Sales Input'!K126,IF('Consolidated Sales'!$C$2=10,'Sales Input'!L126,IF('Consolidated Sales'!$C$2=11,'Sales Input'!M126,IF('Consolidated Sales'!$C$2=12,'Sales Input'!N126,IF('Consolidated Sales'!$C$2=13,'Sales Input'!O126,0))))))))))))) -> 0 | H7: =C7-E7-G7-I7-K7 -> 0 | I7: =IF('Consolidated Sales'!$C$2=1,'Sales Input'!C148,IF('Consolidated Sales'!$C$2=2,'Sales Input'!D148,IF('Consolidated Sales'!$C$2=3,'Sales Input'!E148,IF('Consolidated Sales'!$C$2=4,'Sales Input'!F148,IF('Consolidated Sales'!$C$2=5,'Sales Input'!G148,IF('Consolidated Sales'!$C$2=6,'Sales Input'!H148,IF('Consolidated Sales'!$C$2=7,'Sales Input'!I148,IF('Consolidated Sales'!$C$2=8,'Sales Input'!J148,IF('Consolidated Sales'!$C$2=9,'Sales Input'!K148,IF('Consolidated Sales'!$C$2=10,'Sales Input'!L148,IF('Consolidated Sales'!$C$2=11,'Sales Input'!M148,IF('Consolidated Sales'!$C$2=12,'Sales Input'!N148,IF('Consolidated Sales'!$C$2=13,'Sales Input'!O148,0))))))))))))) -> 0 | J7: =C7-E7-G7-I7-K7 -> 0 | K7: =IF('Consolidated Sales'!$C$2=1,'Sales Input'!C170,IF('Consolidated Sales'!$C$2=2,'Sales Input'!D170,IF('Consolidated Sales'!$C$2=3,'Sales Input'!E170,IF('Consolidated Sales'!$C$2=4,'Sales Input'!F170,IF('Consolidated Sales'!$C$2=5,'Sales Input'!G170,IF('Consolidated Sales'!$C$2=6,'Sales Input'!H170,IF('Consolidated Sales'!$C$2=7,'Sales Input'!I170,IF('Consolidated Sales'!$C$2=8,'Sales Input'!J170,IF('Consolidated Sales'!$C$2=9,'Sales Input'!K170,IF('Consolidated Sales'!$C$2=10,'Sales Input'!L170,IF('Consolidated Sales'!$C$2=11,'Sales Input'!M170,IF('Consolidated Sales'!$C$2=12,'Sales Input'!N170,IF('Consolidated Sales'!$C$2=13,'Sales Input'!O170,0))))))))))))) -> 0 | L7: =C7-E7-G7-I7-K7 -> 0
B8: Bakeries | C8: =IF('Consolidated Sales'!$C$2=1,'Sales Input'!C77,IF('Consolidated Sales'!$C$2=2,'Sales Input'!D77,IF('Consolidated Sales'!$C$2=3,'Sales Input'!E77,IF('Consolidated Sales'!$C$2=4,'Sales Input'!F77,IF('Consolidated Sales'!$C$2=5,'Sales Input'!G77,IF('Consolidated Sales'!$C$2=6,'Sales Input'!H77,IF('Consolidated Sales'!$C$2=7,'Sales Input'!I77,IF('Consolidated Sales'!$C$2=8,'Sales Input'!J77,IF('Consolidated Sales'!$C$2=9,'Sales Input'!K77,IF('Consolidated Sales'!$C$2=10,'Sales Input'!L77,IF('Consolidated Sales'!$C$2=11,'Sales Input'!M77,IF('Consolidated Sales'!$C$2=12,'Sales Input'!N77,IF('Consolidated Sales'!$C$2=13,'Sales Input'!O77,0))))))))))))) -> 104700 | D8: =SUM(C8-E8-G8-I8-K8) -> 0 | E8: =IF('Consolidated Sales'!$C$2=1,'Sales Input'!C105,IF('Consolidated Sales'!$C$2=2,'Sales Input'!D105,IF('Consolidated Sales'!$C$2=3,'Sales Input'!E105,IF('Consolidated Sales'!$C$2=4,'Sales Input'!F105,IF('Consolidated Sales'!$C$2=5,'Sales Input'!G105,IF('Consolidated Sales'!$C$2=6,'Sales Input'!H105,IF('Consolidated Sales'!$C$2=7,'Sales Input'!I105,IF('Consolidated Sales'!$C$2=8,'Sales Input'!J105,IF('Consolidated Sales'!$C$2=9,'Sales Input'!K105,IF('Consolidated Sales'!$C$2=10,'Sales Input'!L105,IF('Consolidated Sales'!$C$2=11,'Sales Input'!M105,IF('Consolidated Sales'!$C$2=12,'Sales Input'!N105,IF('Consolidated Sales'!$C$2=13,'Sales Input'!O105,0))))))))))))) -> 0 | F8: =SUM(C8-E8-G8-I8-K8) -> 0 | G8: =IF('Consolidated Sales'!$C$2=1,'Sales Input'!C127,IF('Consolidated Sales'!$C$2=2,'Sales Input'!D127,IF('Consolidated Sales'!$C$2=3,'Sales Input'!E127,IF('Consolidated Sales'!$C$2=4,'Sales Input'!F127,IF('Consolidated Sales'!$C$2=5,'Sales Input'!G127,IF('Consolidated Sales'!$C$2=6,'Sales Input'!H127,IF('Consolidated Sales'!$C$2=7,'Sales Input'!I127,IF('Consolidated Sales'!$C$2=8,'Sales Input'!J127,IF('Consolidated Sales'!$C$2=9,'Sales Input'!K127,IF('Consolidated Sales'!$C$2=10,'Sales Input'!L127,IF('Consolidated Sales'!$C$2=11,'Sales Input'!M127,IF('Consolidated Sales'!$C$2=12,'Sales Input'!N127,IF('Consolidated Sales'!$C$2=13,'Sales Input'!O127,0))))))))))))) -> 0 | H8: =C8-E8-G8-I8-K8 -> 0 | I8: =IF('Consolidated Sales'!$C$2=1,'Sales Input'!C149,IF('Consolidated Sales'!$C$2=2,'Sales Input'!D149,IF('Consolidated Sales'!$C$2=3,'Sales Input'!E149,IF('Consolidated Sales'!$C$2=4,'Sales Input'!F149,IF('Consolidated Sales'!$C$2=5,'Sales Input'!G149,IF('Consolidated Sales'!$C$2=6,'Sales Input'!H149,IF('Consolidated Sales'!$C$2=7,'Sales Input'!I149,IF('Consolidated Sales'!$C$2=8,'Sales Input'!J149,IF('Consolidated Sales'!$C$2=9,'Sales Input'!K149,IF('Consolidated Sales'!$C$2=10,'Sales Input'!L149,IF('Consolidated Sales'!$C$2=11,'Sales Input'!M149,IF('Consolidated Sales'!$C$2=12,'Sales Input'!N149,IF('Consolidated Sales'!$C$2=13,'Sales Input'!O149,0))))))))))))) -> 104700 | J8: =C8-E8-G8-I8-K8 -> 0 | K8: =IF('Consolidated Sales'!$C$2=1,'Sales Input'!C171,IF('Consolidated Sales'!$C$2=2,'Sales Input'!D171,IF('Consolidated Sales'!$C$2=3,'Sales Input'!E171,IF('Consolidated Sales'!$C$2=4,'Sales Input'!F171,IF('Consolidated Sales'!$C$2=5,'Sales Input'!G171,IF('Consolidated Sales'!$C$2=6,'Sales Input'!H171,IF('Consolidated Sales'!$C$2=7,'Sales Input'!I171,IF('Consolidated Sales'!$C$2=8,'Sales Input'!J171,IF('Consolidated Sales'!$C$2=9,'Sales Input'!K171,IF('Consolidated Sales'!$C$2=10,'Sales Input'!L171,IF('Consolidated Sales'!$C$2=11,'Sales Input'!M171,IF('Consolidated Sales'!$C$2=12,'Sales Input'!N171,IF('Consolidated Sales'!$C$2=13,'Sales Input'!O171,0))))))))))))) -> 0 | L8: =C8-E8-G8-I8-K8 -> 0
B9: Suncrest Ltd | C9: =IF('Consolidated Sales'!$C$2=1,'Sales Input'!C78,IF('Consolidated Sales'!$C$2=2,'Sales Input'!D78,IF('Consolidated Sales'!$C$2=3,'Sales Input'!E78,IF('Consolidated Sales'!$C$2=4,'Sales Input'!F78,IF('Consolidated Sales'!$C$2=5,'Sales Input'!G78,IF('Consolidated Sales'!$C$2=6,'Sales Input'!H78,IF('Consolidated Sales'!$C$2=7,'Sales Input'!I78,IF('Consolidated Sales'!$C$2=8,'Sales Input'!J78,IF('Consolidated Sales'!$C$2=9,'Sales Input'!K78,IF('Consolidated Sales'!$C$2=10,'Sales Input'!L78,IF('Consolidated Sales'!$C$2=11,'Sales Input'!M78,IF('Consolidated Sales'!$C$2=12,'Sales Input'!N78,IF('Consolidated Sales'!$C$2=13,'Sales Input'!O78,0))))))))))))) -> 0 | D9: =SUM(C9-E9-G9-I9-K9) -> 0 | E9: =IF('Consolidated Sales'!$C$2=1,'Sales Input'!C106,IF('Consolidated Sales'!$C$2=2,'Sales Input'!D106,IF('Consolidated Sales'!$C$2=3,'Sales Input'!E106,IF('Consolidated Sales'!$C$2=4,'Sales Input'!F106,IF('Consolidated Sales'!$C$2=5,'Sales Input'!G106,IF('Consolidated Sales'!$C$2=6,'Sales Input'!H106,IF('Consolidated Sales'!$C$2=7,'Sales Input'!I106,IF('Consolidated Sales'!$C$2=8,'Sales Input'!J106,IF('Consolidated Sales'!$C$2=9,'Sales Input'!K106,IF('Consolidated Sales'!$C$2=10,'Sales Input'!L106,IF('Consolidated Sales'!$C$2=11,'Sales Input'!M106,IF('Consolidated Sales'!$C$2=12,'Sales Input'!N106,IF('Consolidated Sales'!$C$2=13,'Sales Input'!O106,0))))))))))))) -> 0 | F9: =SUM(C9-E9-G9-I9-K9) -> 0 | G9: =IF('Consolidated Sales'!$C$2=1,'Sales Input'!C128,IF('Consolidated Sales'!$C$2=2,'Sales Input'!D128,IF('Consolidated Sales'!$C$2=3,'Sales Input'!E128,IF('Consolidated Sales'!$C$2=4,'Sales Input'!F128,IF('Consolidated Sales'!$C$2=5,'Sales Input'!G128,IF('Consolidated Sales'!$C$2=6,'Sales Input'!H128,IF('Consolidated Sales'!$C$2=7,'Sales Input'!I128,IF('Consolidated Sales'!$C$2=8,'Sales Input'!J128,IF('Consolidated Sales'!$C$2=9,'Sales Input'!K128,IF('Consolidated Sales'!$C$2=10,'Sales Input'!L128,IF('Consolidated Sales'!$C$2=11,'Sales Input'!M128,IF('Consolidated Sales'!$C$2=12,'Sales Input'!N128,IF('Consolidated Sales'!$C$2=13,'Sales Input'!O128,0))))))))))))) -> 0 | H9: =C9-E9-G9-I9-K9 -> 0 | I9: =IF('Consolidated Sales'!$C$2=1,'Sales Input'!C150,IF('Consolidated Sales'!$C$2=2,'Sales Input'!D150,IF('Consolidated Sales'!$C$2=3,'Sales Input'!E150,IF('Consolidated Sales'!$C$2=4,'Sales Input'!F150,IF('Consolidated Sales'!$C$2=5,'Sales Input'!G150,IF('Consolidated Sales'!$C$2=6,'Sales Input'!H150,IF('Consolidated Sales'!$C$2=7,'Sales Input'!I150,IF('Consolidated Sales'!$C$2=8,'Sales Input'!J150,IF('Consolidated Sales'!$C$2=9,'Sales Input'!K150,IF('Consolidated Sales'!$C$2=10,'Sales Input'!L150,IF('Consolidated Sales'!$C$2=11,'Sales Input'!M150,IF('Consolidated Sales'!$C$2=12,'Sales Input'!N150,IF('Consolidated Sales'!$C$2=13,'Sales Input'!O150,0))))))))))))) -> 0 | J9: =C9-E9-G9-I9-K9 -> 0 | K9: =IF('Consolidated Sales'!$C$2=1,'Sales Input'!C172,IF('Consolidated Sales'!$C$2=2,'Sales Input'!D172,IF('Consolidated Sales'!$C$2=3,'Sales Input'!E172,IF('Consolidated Sales'!$C$2=4,'Sales Input'!F172,IF('Consolidated Sales'!$C$2=5,'Sales Input'!G172,IF('Consolidated Sales'!$C$2=6,'Sales Input'!H172,IF('Consolidated Sales'!$C$2=7,'Sales Input'!I172,IF('Consolidated Sales'!$C$2=8,'Sales Input'!J172,IF('Consolidated Sales'!$C$2=9,'Sales Input'!K172,IF('Consolidated Sales'!$C$2=10,'Sales Input'!L172,IF('Consolidated Sales'!$C$2=11,'Sales Input'!M172,IF('Consolidated Sales'!$C$2=12,'Sales Input'!N172,IF('Consolidated Sales'!$C$2=13,'Sales Input'!O172,0))))))))))))) -> 0 | L9: =C9-E9-G9-I9-K9 -> 0
B10: Cold Chain | C10: =IF('Consolidated Sales'!$C$2=1,'Sales Input'!C79,IF('Consolidated Sales'!$C$2=2,'Sales Input'!D79,IF('Consolidated Sales'!$C$2=3,'Sales Input'!E79,IF('Consolidated Sales'!$C$2=4,'Sales Input'!F79,IF('Consolidated Sales'!$C$2=5,'Sales Input'!G79,IF('Consolidated Sales'!$C$2=6,'Sales Input'!H79,IF('Consolidated Sales'!$C$2=7,'Sales Input'!I79,IF('Consolidated Sales'!$C$2=8,'Sales Input'!J79,IF('Consolidated Sales'!$C$2=9,'Sales Input'!K79,IF('Consolidated Sales'!$C$2=10,'Sales Input'!L79,IF('Consolidated Sales'!$C$2=11,'Sales Input'!M79,IF('Consolidated Sales'!$C$2=12,'Sales Input'!N79,IF('Consolidated Sales'!$C$2=13,'Sales Input'!O79,0))))))))))))) -> 0 | D10: =SUM(C10-E10-G10-I10-K10) -> 0 | E10: =IF('Consolidated Sales'!$C$2=1,'Sales Input'!C107,IF('Consolidated Sales'!$C$2=2,'Sales Input'!D107,IF('Consolidated Sales'!$C$2=3,'Sales Input'!E107,IF('Consolidated Sales'!$C$2=4,'Sales Input'!F107,IF('Consolidated Sales'!$C$2=5,'Sales Input'!G107,IF('Consolidated Sales'!$C$2=6,'Sales Input'!H107,IF('Consolidated Sales'!$C$2=7,'Sales Input'!I107,IF('Consolidated Sales'!$C$2=8,'Sales Input'!J107,IF('Consolidated Sales'!$C$2=9,'Sales Input'!K107,IF('Consolidated Sales'!$C$2=10,'Sales Input'!L107,IF('Consolidated Sales'!$C$2=11,'Sales Input'!M107,IF('Consolidated Sales'!$C$2=12,'Sales Input'!N107,IF('Consolidated Sales'!$C$2=13,'Sales Input'!O107,0))))))))))))) -> 0 | F10: =SUM(C10-E10-G10-I10-K10) -> 0 | G10: =IF('Consolidated Sales'!$C$2=1,'Sales Input'!C129,IF('Consolidated Sales'!$C$2=2,'Sales Input'!D129,IF('Consolidated Sales'!$C$2=3,'Sales Input'!E129,IF('Consolidated Sales'!$C$2=4,'Sales Input'!F129,IF('Consolidated Sales'!$C$2=5,'Sales Input'!G129,IF('Consolidated Sales'!$C$2=6,'Sales Input'!H129,IF('Consolidated Sales'!$C$2=7,'Sales Input'!I129,IF('Consolidated Sales'!$C$2=8,'Sales Input'!J129,IF('Consolidated Sales'!$C$2=9,'Sales Input'!K129,IF('Consolidated Sales'!$C$2=10,'Sales Input'!L129,IF('Consolidated Sales'!$C$2=11,'Sales Input'!M129,IF('Consolidated Sales'!$C$2=12,'Sales Input'!N129,IF('Consolidated Sales'!$C$2=13,'Sales Input'!O129,0))))))))))))) -> 0 | H10: =C10-E10-G10-I10-K10 -> 0 | I10: =IF('Consolidated Sales'!$C$2=1,'Sales Input'!C151,IF('Consolidated Sales'!$C$2=2,'Sales Input'!D151,IF('Consolidated Sales'!$C$2=3,'Sales Input'!E151,IF('Consolidated Sales'!$C$2=4,'Sales Input'!F151,IF('Consolidated Sales'!$C$2=5,'Sales Input'!G151,IF('Consolidated Sales'!$C$2=6,'Sales Input'!H151,IF('Consolidated Sales'!$C$2=7,'Sales Input'!I151,IF('Consolidated Sales'!$C$2=8,'Sales Input'!J151,IF('Consolidated Sales'!$C$2=9,'Sales Input'!K151,IF('Consolidated Sales'!$C$2=10,'Sales Input'!L151,IF('Consolidated Sales'!$C$2=11,'Sales Input'!M151,IF('Consolidated Sales'!$C$2=12,'Sales Input'!N151,IF('Consolidated Sales'!$C$2=13,'Sales Input'!O151,0))))))))))))) -> 0 | J10: =C10-E10-G10-I10-K10 -> 0 | K10: =IF('Consolidated Sales'!$C$2=1,'Sales Input'!C173,IF('Consolidated Sales'!$C$2=2,'Sales Input'!D173,IF('Consolidated Sales'!$C$2=3,'Sales Input'!E173,IF('Consolidated Sales'!$C$2=4,'Sales Input'!F173,IF('Consolidated Sales'!$C$2=5,'Sales Input'!G173,IF('Consolidated Sales'!$C$2=6,'Sales Input'!H173,IF('Consolidated Sales'!$C$2=7,'Sales Input'!I173,IF('Consolidated Sales'!$C$2=8,'Sales Input'!J173,IF('Consolidated Sales'!$C$2=9,'Sales Input'!K173,IF('Consolidated Sales'!$C$2=10,'Sales Input'!L173,IF('Consolidated Sales'!$C$2=11,'Sales Input'!M173,IF('Consolidated Sales'!$C$2=12,'Sales Input'!N173,IF('Consolidated Sales'!$C$2=13,'Sales Input'!O173,0))))))))))))) -> 0 | L10: =C10-E10-G10-I10-K10 -> 0
B11: Unilever | C11: =IF('Consolidated Sales'!$C$2=1,'Sales Input'!C80,IF('Consolidated Sales'!$C$2=2,'Sales Input'!D80,IF('Consolidated Sales'!$C$2=3,'Sales Input'!E80,IF('Consolidated Sales'!$C$2=4,'Sales Input'!F80,IF('Consolidated Sales'!$C$2=5,'Sales Input'!G80,IF('Consolidated Sales'!$C$2=6,'Sales Input'!H80,IF('Consolidated Sales'!$C$2=7,'Sales Input'!I80,IF('Consolidated Sales'!$C$2=8,'Sales Input'!J80,IF('Consolidated Sales'!$C$2=9,'Sales Input'!K80,IF('Consolidated Sales'!$C$2=10,'Sales Input'!L80,IF('Consolidated Sales'!$C$2=11,'Sales Input'!M80,IF('Consolidated Sales'!$C$2=12,'Sales Input'!N80,IF('Consolidated Sales'!$C$2=13,'Sales Input'!O80,0))))))))))))) -> 0 | D11: =SUM(C11-E11-G11-I11-K11) -> 0 | E11: =IF('Consolidated Sales'!$C$2=1,'Sales Input'!C108,IF('Consolidated Sales'!$C$2=2,'Sales Input'!D108,IF('Consolidated Sales'!$C$2=3,'Sales Input'!E108,IF('Consolidated Sales'!$C$2=4,'Sales Input'!F108,IF('Consolidated Sales'!$C$2=5,'Sales Input'!G108,IF('Consolidated Sales'!$C$2=6,'Sales Input'!H108,IF('Consolidated Sales'!$C$2=7,'Sales Input'!I108,IF('Consolidated Sales'!$C$2=8,'Sales Input'!J108,IF('Consolidated Sales'!$C$2=9,'Sales Input'!K108,IF('Consolidated Sales'!$C$2=10,'Sales Input'!L108,IF('Consolidated Sales'!$C$2=11,'Sales Input'!M108,IF('Consolidated Sales'!$C$2=12,'Sales Input'!N108,IF('Consolidated Sales'!$C$2=13,'Sales Input'!O108,0))))))))))))) -> 0 | F11: =SUM(C11-E11-G11-I11-K11) -> 0 | G11: =IF('Consolidated Sales'!$C$2=1,'Sales Input'!C130,IF('Consolidated Sales'!$C$2=2,'Sales Input'!D130,IF('Consolidated Sales'!$C$2=3,'Sales Input'!E130,IF('Consolidated Sales'!$C$2=4,'Sales Input'!F130,IF('Consolidated Sales'!$C$2=5,'Sales Input'!G130,IF('Consolidated Sales'!$C$2=6,'Sales Input'!H130,IF('Consolidated Sales'!$C$2=7,'Sales Input'!I130,IF('Consolidated Sales'!$C$2=8,'Sales Input'!J130,IF('Consolidated Sales'!$C$2=9,'Sales Input'!K130,IF('Consolidated Sales'!$C$2=10,'Sales Input'!L130,IF('Consolidated Sales'!$C$2=11,'Sales Input'!M130,IF('Consolidated Sales'!$C$2=12,'Sales Input'!N130,IF('Consolidated Sales'!$C$2=13,'Sales Input'!O130,0))))))))))))) -> 0 | H11: =C11-E11-G11-I11-K11 -> 0 | I11: =IF('Consolidated Sales'!$C$2=1,'Sales Input'!C152,IF('Consolidated Sales'!$C$2=2,'Sales Input'!D152,IF('Consolidated Sales'!$C$2=3,'Sales Input'!E152,IF('Consolidated Sales'!$C$2=4,'Sales Input'!F152,IF('Consolidated Sales'!$C$2=5,'Sales Input'!G152,IF('Consolidated Sales'!$C$2=6,'Sales Input'!H152,IF('Consolidated Sales'!$C$2=7,'Sales Input'!I152,IF('Consolidated Sales'!$C$2=8,'Sales Input'!J152,IF('Consolidated Sales'!$C$2=9,'Sales Input'!K152,IF('Consolidated Sales'!$C$2=10,'Sales Input'!L152,IF('Consolidated Sales'!$C$2=11,'Sales Input'!M152,IF('Consolidated Sales'!$C$2=12,'Sales Input'!N152,IF('Consolidated Sales'!$C$2=13,'Sales Input'!O152,0))))))))))))) -> 0 | J11: =C11-E11-G11-I11-K11 -> 0 | K11: =IF('Consolidated Sales'!$C$2=1,'Sales Input'!C174,IF('Consolidated Sales'!$C$2=2,'Sales Input'!D174,IF('Consolidated Sales'!$C$2=3,'Sales Input'!E174,IF('Consolidated Sales'!$C$2=4,'Sales Input'!F174,IF('Consolidated Sales'!$C$2=5,'Sales Input'!G174,IF('Consolidated Sales'!$C$2=6,'Sales Input'!H174,IF('Consolidated Sales'!$C$2=7,'Sales Input'!I174,IF('Consolidated Sales'!$C$2=8,'Sales Input'!J174,IF('Consolidated Sales'!$C$2=9,'Sales Input'!K174,IF('Consolidated Sales'!$C$2=10,'Sales Input'!L174,IF('Consolidated Sales'!$C$2=11,'Sales Input'!M174,IF('Consolidated Sales'!$C$2=12,'Sales Input'!N174,IF('Consolidated Sales'!$C$2=13,'Sales Input'!O174,0))))))))))))) -> 0 | L11: =C11-E11-G11-I11-K11 -> 0
B12: Rab Processors | C12: =IF('Consolidated Sales'!$C$2=1,'Sales Input'!C81,IF('Consolidated Sales'!$C$2=2,'Sales Input'!D81,IF('Consolidated Sales'!$C$2=3,'Sales Input'!E81,IF('Consolidated Sales'!$C$2=4,'Sales Input'!F81,IF('Consolidated Sales'!$C$2=5,'Sales Input'!G81,IF('Consolidated Sales'!$C$2=6,'Sales Input'!H81,IF('Consolidated Sales'!$C$2=7,'Sales Input'!I81,IF('Consolidated Sales'!$C$2=8,'Sales Input'!J81,IF('Consolidated Sales'!$C$2=9,'Sales Input'!K81,IF('Consolidated Sales'!$C$2=10,'Sales Input'!L81,IF('Consolidated Sales'!$C$2=11,'Sales Input'!M81,IF('Consolidated Sales'!$C$2=12,'Sales Input'!N81,IF('Consolidated Sales'!$C$2=13,'Sales Input'!O81,0))))))))))))) -> 0 | D12: =SUM(C12-E12-G12-I12-K12) -> 0 | E12: =IF('Consolidated Sales'!$C$2=1,'Sales Input'!C109,IF('Consolidated Sales'!$C$2=2,'Sales Input'!D109,IF('Consolidated Sales'!$C$2=3,'Sales Input'!E109,IF('Consolidated Sales'!$C$2=4,'Sales Input'!F109,IF('Consolidated Sales'!$C$2=5,'Sales Input'!G109,IF('Consolidated Sales'!$C$2=6,'Sales Input'!H109,IF('Consolidated Sales'!$C$2=7,'Sales Input'!I109,IF('Consolidated Sales'!$C$2=8,'Sales Input'!J109,IF('Consolidated Sales'!$C$2=9,'Sales Input'!K109,IF('Consolidated Sales'!$C$2=10,'Sales Input'!L109,IF('Consolidated Sales'!$C$2=11,'Sales Input'!M109,IF('Consolidated Sales'!$C$2=12,'Sales Input'!N109,IF('Consolidated Sales'!$C$2=13,'Sales Input'!O109,0))))))))))))) -> 0 | F12: =SUM(C12-E12-G12-I12-K12) -> 0 | G12: =IF('Consolidated Sales'!$C$2=1,'Sales Input'!C131,IF('Consolidated Sales'!$C$2=2,'Sales Input'!D131,IF('Consolidated Sales'!$C$2=3,'Sales Input'!E131,IF('Consolidated Sales'!$C$2=4,'Sales Input'!F131,IF('Consolidated Sales'!$C$2=5,'Sales Input'!G131,IF('Consolidated Sales'!$C$2=6,'Sales Input'!H131,IF('Consolidated Sales'!$C$2=7,'Sales Input'!I131,IF('Consolidated Sales'!$C$2=8,'Sales Input'!J131,IF('Consolidated Sales'!$C$2=9,'Sales Input'!K131,IF('Consolidated Sales'!$C$2=10,'Sales Input'!L131,IF('Consolidated Sales'!$C$2=11,'Sales Input'!M131,IF('Consolidated Sales'!$C$2=12,'Sales Input'!N131,IF('Consolidated Sales'!$C$2=13,'Sales Input'!O131,0))))))))))))) -> 0 | H12: =C12-E12-G12-I12-K12 -> 0 | I12: =IF('Consolidated Sales'!$C$2=1,'Sales Input'!C153,IF('Consolidated Sales'!$C$2=2,'Sales Input'!D153,IF('Consolidated Sales'!$C$2=3,'Sales Input'!E153,IF('Consolidated Sales'!$C$2=4,'Sales Input'!F153,IF('Consolidated Sales'!$C$2=5,'Sales Input'!G153,IF('Consolidated Sales'!$C$2=6,'Sales Input'!H153,IF('Consolidated Sales'!$C$2=7,'Sales Input'!I153,IF('Consolidated Sales'!$C$2=8,'Sales Input'!J153,IF('Consolidated Sales'!$C$2=9,'Sales Input'!K153,IF('Consolidated Sales'!$C$2=10,'Sales Input'!L153,IF('Consolidated Sales'!$C$2=11,'Sales Input'!M153,IF('Consolidated Sales'!$C$2=12,'Sales Input'!N153,IF('Consolidated Sales'!$C$2=13,'Sales Input'!O153,0))))))))))))) -> 0 | J12: =C12-E12-G12-I12-K12 -> 0 | K12: =IF('Consolidated Sales'!$C$2=1,'Sales Input'!C175,IF('Consolidated Sales'!$C$2=2,'Sales Input'!D175,IF('Consolidated Sales'!$C$2=3,'Sales Input'!E175,IF('Consolidated Sales'!$C$2=4,'Sales Input'!F175,IF('Consolidated Sales'!$C$2=5,'Sales Input'!G175,IF('Consolidated Sales'!$C$2=6,'Sales Input'!H175,IF('Consolidated Sales'!$C$2=7,'Sales Input'!I175,IF('Consolidated Sales'!$C$2=8,'Sales Input'!J175,IF('Consolidated Sales'!$C$2=9,'Sales Input'!K175,IF('Consolidated Sales'!$C$2=10,'Sales Input'!L175,IF('Consolidated Sales'!$C$2=11,'Sales Input'!M175,IF('Consolidated Sales'!$C$2=12,'Sales Input'!N175,IF('Consolidated Sales'!$C$2=13,'Sales Input'!O175,0))))))))))))) -> 0 | L12: =C12-E12-G12-I12-K12 -> 0
B13: Kwacha Fund | C13: =IF('Consolidated Sales'!$C$2=1,'Sales Input'!C82,IF('Consolidated Sales'!$C$2=2,'Sales Input'!D82,IF('Consolidated Sales'!$C$2=3,'Sales Input'!E82,IF('Consolidated Sales'!$C$2=4,'Sales Input'!F82,IF('Consolidated Sales'!$C$2=5,'Sales Input'!G82,IF('Consolidated Sales'!$C$2=6,'Sales Input'!H82,IF('Consolidated Sales'!$C$2=7,'Sales Input'!I82,IF('Consolidated Sales'!$C$2=8,'Sales Input'!J82,IF('Consolidated Sales'!$C$2=9,'Sales Input'!K82,IF('Consolidated Sales'!$C$2=10,'Sales Input'!L82,IF('Consolidated Sales'!$C$2=11,'Sales Input'!M82,IF('Consolidated Sales'!$C$2=12,'Sales Input'!N82,IF('Consolidated Sales'!$C$2=13,'Sales Input'!O82,0))))))))))))) -> 3323620.5 | D13: =SUM(C13-E13-G13-I13-K13) -> 0 | E13: =IF('Consolidated Sales'!$C$2=1,'Sales Input'!C110,IF('Consolidated Sales'!$C$2=2,'Sales Input'!D110,IF('Consolidated Sales'!$C$2=3,'Sales Input'!E110,IF('Consolidated Sales'!$C$2=4,'Sales Input'!F110,IF('Consolidated Sales'!$C$2=5,'Sales Input'!G110,IF('Consolidated Sales'!$C$2=6,'Sales Input'!H110,IF('Consolidated Sales'!$C$2=7,'Sales Input'!I110,IF('Consolidated Sales'!$C$2=8,'Sales Input'!J110,IF('Consolidated Sales'!$C$2=9,'Sales Input'!K110,IF('Consolidated Sales'!$C$2=10,'Sales Input'!L110,IF('Consolidated Sales'!$C$2=11,'Sales Input'!M110,IF('Consolidated Sales'!$C$2=12,'Sales Input'!N110,IF('Consolidated Sales'!$C$2=13,'Sales Input'!O110,0))))))))))))) -> 0 | F13: =SUM(C13-E13-G13-I13-K13) -> 0 | G13: =IF('Consolidated Sales'!$C$2=1,'Sales Input'!C132,IF('Consolidated Sales'!$C$2=2,'Sales Input'!D132,IF('Consolidated Sales'!$C$2=3,'Sales Input'!E132,IF('Consolidated Sales'!$C$2=4,'Sales Input'!F132,IF('Consolidated Sales'!$C$2=5,'Sales Input'!G132,IF('Consolidated Sales'!$C$2=6,'Sales Input'!H132,IF('Consolidated Sales'!$C$2=7,'Sales Input'!I132,IF('Consolidated Sales'!$C$2=8,'Sales Input'!J132,IF('Consolidated Sales'!$C$2=9,'Sales Input'!K132,IF('Consolidated Sales'!$C$2=10,'Sales Input'!L132,IF('Consolidated Sales'!$C$2=11,'Sales Input'!M132,IF('Consolidated Sales'!$C$2=12,'Sales Input'!N132,IF('Consolidated Sales'!$C$2=13,'Sales Input'!O132,0))))))))))))) -> 3323620.5 | H13: =C13-E13-G13-I13-K13 -> 0 | I13: =IF('Consolidated Sales'!$C$2=1,'Sales Input'!C154,IF('Consolidated Sales'!$C$2=2,'Sales Input'!D154,IF('Consolidated Sales'!$C$2=3,'Sales Input'!E154,IF('Consolidated Sales'!$C$2=4,'Sales Input'!F154,IF('Consolidated Sales'!$C$2=5,'Sales Input'!G154,IF('Consolidated Sales'!$C$2=6,'Sales Input'!H154,IF('Consolidated Sales'!$C$2=7,'Sales Input'!I154,IF('Consolidated Sales'!$C$2=8,'Sales Input'!J154,IF('Consolidated Sales'!$C$2=9,'Sales Input'!K154,IF('Consolidated Sales'!$C$2=10,'Sales Input'!L154,IF('Consolidated Sales'!$C$2=11,'Sales Input'!M154,IF('Consolidated Sales'!$C$2=12,'Sales Input'!N154,IF('Consolidated Sales'!$C$2=13,'Sales Input'!O154,0))))))))))))) -> 0 | J13: =C13-E13-G13-I13-K13 -> 0 | K13: =IF('Consolidated Sales'!$C$2=1,'Sales Input'!C176,IF('Consolidated Sales'!$C$2=2,'Sales Input'!D176,IF('Consolidated Sales'!$C$2=3,'Sales Input'!E176,IF('Consolidated Sales'!$C$2=4,'Sales Input'!F176,IF('Consolidated Sales'!$C$2=5,'Sales Input'!G176,IF('Consolidated Sales'!$C$2=6,'Sales Input'!H176,IF('Consolidated Sales'!$C$2=7,'Sales Input'!I176,IF('Consolidated Sales'!$C$2=8,'Sales Input'!J176,IF('Consolidated Sales'!$C$2=9,'Sales Input'!K176,IF('Consolidated Sales'!$C$2=10,'Sales Input'!L176,IF('Consolidated Sales'!$C$2=11,'Sales Input'!M176,IF('Consolidated Sales'!$C$2=12,'Sales Input'!N176,IF('Consolidated Sales'!$C$2=13,'Sales Input'!O176,0))))))))))))) -> 0 | L13: =C13-E13-G13-I13-K13 -> 0
B14: Ekhaya Farms | C14: =IF('Consolidated Sales'!$C$2=1,'Sales Input'!C83,IF('Consolidated Sales'!$C$2=2,'Sales Input'!D83,IF('Consolidated Sales'!$C$2=3,'Sales Input'!E83,IF('Consolidated Sales'!$C$2=4,'Sales Input'!F83,IF('Consolidated Sales'!$C$2=5,'Sales Input'!G83,IF('Consolidated Sales'!$C$2=6,'Sales Input'!H83,IF('Consolidated Sales'!$C$2=7,'Sales Input'!I83,IF('Consolidated Sales'!$C$2=8,'Sales Input'!J83,IF('Consolidated Sales'!$C$2=9,'Sales Input'!K83,IF('Consolidated Sales'!$C$2=10,'Sales Input'!L83,IF('Consolidated Sales'!$C$2=11,'Sales Input'!M83,IF('Consolidated Sales'!$C$2=12,'Sales Input'!N83,IF('Consolidated Sales'!$C$2=13,'Sales Input'!O83,0))))))))))))) -> 0 | D14: =SUM(C14-E14-G14-I14-K14) -> 0 | E14: =IF('Consolidated Sales'!$C$2=1,'Sales Input'!C111,IF('Consolidated Sales'!$C$2=2,'Sales Input'!D111,IF('Consolidated Sales'!$C$2=3,'Sales Input'!E111,IF('Consolidated Sales'!$C$2=4,'Sales Input'!F111,IF('Consolidated Sales'!$C$2=5,'Sales Input'!G111,IF('Consolidated Sales'!$C$2=6,'Sales Input'!H111,IF('Consolidated Sales'!$C$2=7,'Sales Input'!I111,IF('Consolidated Sales'!$C$2=8,'Sales Input'!J111,IF('Consolidated Sales'!$C$2=9,'Sales Input'!K111,IF('Consolidated Sales'!$C$2=10,'Sales Input'!L111,IF('Consolidated Sales'!$C$2=11,'Sales Input'!M111,IF('Consolidated Sales'!$C$2=12,'Sales Input'!N111,IF('Consolidated Sales'!$C$2=13,'Sales Input'!O111,0))))))))))))) -> 0 | F14: =SUM(C14-E14-G14-I14-K14) -> 0 | G14: =IF('Consolidated Sales'!$C$2=1,'Sales Input'!C133,IF('Consolidated Sales'!$C$2=2,'Sales Input'!D133,IF('Consolidated Sales'!$C$2=3,'Sales Input'!E133,IF('Consolidated Sales'!$C$2=4,'Sales Input'!F133,IF('Consolidated Sales'!$C$2=5,'Sales Input'!G133,IF('Consolidated Sales'!$C$2=6,'Sales Input'!H133,IF('Consolidated Sales'!$C$2=7,'Sales Input'!I133,IF('Consolidated Sales'!$C$2=8,'Sales Input'!J133,IF('Consolidated Sales'!$C$2=9,'Sales Input'!K133,IF('Consolidated Sales'!$C$2=10,'Sales Input'!L133,IF('Consolidated Sales'!$C$2=11,'Sales Input'!M133,IF('Consolidated Sales'!$C$2=12,'Sales Input'!N133,IF('Consolidated Sales'!$C$2=13,'Sales Input'!O133,0))))))))))))) -> 0 | H14: =C14-E14-G14-I14-K14 -> 0 | I14: =IF('Consolidated Sales'!$C$2=1,'Sales Input'!C155,IF('Consolidated Sales'!$C$2=2,'Sales Input'!D155,IF('Consolidated Sales'!$C$2=3,'Sales Input'!E155,IF('Consolidated Sales'!$C$2=4,'Sales Input'!F155,IF('Consolidated Sales'!$C$2=5,'Sales Input'!G155,IF('Consolidated Sales'!$C$2=6,'Sales Input'!H155,IF('Consolidated Sales'!$C$2=7,'Sales Input'!I155,IF('Consolidated Sales'!$C$2=8,'Sales Input'!J155,IF('Consolidated Sales'!$C$2=9,'Sales Input'!K155,IF('Consolidated Sales'!$C$2=10,'Sales Input'!L155,IF('Consolidated Sales'!$C$2=11,'Sales Input'!M155,IF('Consolidated Sales'!$C$2=12,'Sales Input'!N155,IF('Consolidated Sales'!$C$2=13,'Sales Input'!O155,0))))))))))))) -> 0 | J14: =C14-E14-G14-I14-K14 -> 0 | K14: =IF('Consolidated Sales'!$C$2=1,'Sales Input'!C177,IF('Consolidated Sales'!$C$2=2,'Sales Input'!D177,IF('Consolidated Sales'!$C$2=3,'Sales Input'!E177,IF('Consolidated Sales'!$C$2=4,'Sales Input'!F177,IF('Consolidated Sales'!$C$2=5,'Sales Input'!G177,IF('Consolidated Sales'!$C$2=6,'Sales Input'!H177,IF('Consolidated Sales'!$C$2=7,'Sales Input'!I177,IF('Consolidated Sales'!$C$2=8,'Sales Input'!J177,IF('Consolidated Sales'!$C$2=9,'Sales Input'!K177,IF('Consolidated Sales'!$C$2=10,'Sales Input'!L177,IF('Consolidated Sales'!$C$2=11,'Sales Input'!M177,IF('Consolidated Sales'!$C$2=12,'Sales Input'!N177,IF('Consolidated Sales'!$C$2=13,'Sales Input'!O177,0))))))))))))) -> 0 | L14: =C14-E14-G14-I14-K14 -> 0
B15: Central Poultry | C15: =IF('Consolidated Sales'!$C$2=1,'Sales Input'!C84,IF('Consolidated Sales'!$C$2=2,'Sales Input'!D84,IF('Consolidated Sales'!$C$2=3,'Sales Input'!E84,IF('Consolidated Sales'!$C$2=4,'Sales Input'!F84,IF('Consolidated Sales'!$C$2=5,'Sales Input'!G84,IF('Consolidated Sales'!$C$2=6,'Sales Input'!H84,IF('Consolidated Sales'!$C$2=7,'Sales Input'!I84,IF('Consolidated Sales'!$C$2=8,'Sales Input'!J84,IF('Consolidated Sales'!$C$2=9,'Sales Input'!K84,IF('Consolidated Sales'!$C$2=10,'Sales Input'!L84,IF('Consolidated Sales'!$C$2=11,'Sales Input'!M84,IF('Consolidated Sales'!$C$2=12,'Sales Input'!N84,IF('Consolidated Sales'!$C$2=13,'Sales Input'!O84,0))))))))))))) -> 0 | D15: =SUM(C15-E15-G15-I15-K15) -> 0 | E15: =IF('Consolidated Sales'!$C$2=1,'Sales Input'!C112,IF('Consolidated Sales'!$C$2=2,'Sales Input'!D112,IF('Consolidated Sales'!$C$2=3,'Sales Input'!E112,IF('Consolidated Sales'!$C$2=4,'Sales Input'!F112,IF('Consolidated Sales'!$C$2=5,'Sales Input'!G112,IF('Consolidated Sales'!$C$2=6,'Sales Input'!H112,IF('Consolidated Sales'!$C$2=7,'Sales Input'!I112,IF('Consolidated Sales'!$C$2=8,'Sales Input'!J112,IF('Consolidated Sales'!$C$2=9,'Sales Input'!K112,IF('Consolidated Sales'!$C$2=10,'Sales Input'!L112,IF('Consolidated Sales'!$C$2=11,'Sales Input'!M112,IF('Consolidated Sales'!$C$2=12,'Sales Input'!N112,IF('Consolidated Sales'!$C$2=13,'Sales Input'!O112,0))))))))))))) -> 0 | F15: =SUM(C15-E15-G15-I15-K15) -> 0 | G15: =IF('Consolidated Sales'!$C$2=1,'Sales Input'!C134,IF('Consolidated Sales'!$C$2=2,'Sales Input'!D134,IF('Consolidated Sales'!$C$2=3,'Sales Input'!E134,IF('Consolidated Sales'!$C$2=4,'Sales Input'!F134,IF('Consolidated Sales'!$C$2=5,'Sales Input'!G134,IF('Consolidated Sales'!$C$2=6,'Sales Input'!H134,IF('Consolidated Sales'!$C$2=7,'Sales Input'!I134,IF('Consolidated Sales'!$C$2=8,'Sales Input'!J134,IF('Consolidated Sales'!$C$2=9,'Sales Input'!K134,IF('Consolidated Sales'!$C$2=10,'Sales Input'!L134,IF('Consolidated Sales'!$C$2=11,'Sales Input'!M134,IF('Consolidated Sales'!$C$2=12,'Sales Input'!N134,IF('Consolidated Sales'!$C$2=13,'Sales Input'!O134,0))))))))))))) -> 0 | H15: =C15-E15-G15-I15-K15 -> 0 | I15: =IF('Consolidated Sales'!$C$2=1,'Sales Input'!C156,IF('Consolidated Sales'!$C$2=2,'Sales Input'!D156,IF('Consolidated Sales'!$C$2=3,'Sales Input'!E156,IF('Consolidated Sales'!$C$2=4,'Sales Input'!F156,IF('Consolidated Sales'!$C$2=5,'Sales Input'!G156,IF('Consolidated Sales'!$C$2=6,'Sales Input'!H156,IF('Consolidated Sales'!$C$2=7,'Sales Input'!I156,IF('Consolidated Sales'!$C$2=8,'Sales Input'!J156,IF('Consolidated Sales'!$C$2=9,'Sales Input'!K156,IF('Consolidated Sales'!$C$2=10,'Sales Input'!L156,IF('Consolidated Sales'!$C$2=11,'Sales Input'!M156,IF('Consolidated Sales'!$C$2=12,'Sales Input'!N156,IF('Consolidated Sales'!$C$2=13,'Sales Input'!O156,0))))))))))))) -> 0 | J15: =C15-E15-G15-I15-K15 -> 0 | K15: =IF('Consolidated Sales'!$C$2=1,'Sales Input'!C178,IF('Consolidated Sales'!$C$2=2,'Sales Input'!D178,IF('Consolidated Sales'!$C$2=3,'Sales Input'!E178,IF('Consolidated Sales'!$C$2=4,'Sales Input'!F178,IF('Consolidated Sales'!$C$2=5,'Sales Input'!G178,IF('Consolidated Sales'!$C$2=6,'Sales Input'!H178,IF('Consolidated Sales'!$C$2=7,'Sales Input'!I178,IF('Consolidated Sales'!$C$2=8,'Sales Input'!J178,IF('Consolidated Sales'!$C$2=9,'Sales Input'!K178,IF('Consolidated Sales'!$C$2=10,'Sales Input'!L178,IF('Consolidated Sales'!$C$2=11,'Sales Input'!M178,IF('Consolidated Sales'!$C$2=12,'Sales Input'!N178,IF('Consolidated Sales'!$C$2=13,'Sales Input'!O178,0))))))))))))) -> 0 | L15: =C15-E15-G15-I15-K15 -> 0
B16: Licorice Investment (Burundi Shop) | C16: =IF('Consolidated Sales'!$C$2=1,'Sales Input'!C85,IF('Consolidated Sales'!$C$2=2,'Sales Input'!D85,IF('Consolidated Sales'!$C$2=3,'Sales Input'!E85,IF('Consolidated Sales'!$C$2=4,'Sales Input'!F85,IF('Consolidated Sales'!$C$2=5,'Sales Input'!G85,IF('Consolidated Sales'!$C$2=6,'Sales Input'!H85,IF('Consolidated Sales'!$C$2=7,'Sales Input'!I85,IF('Consolidated Sales'!$C$2=8,'Sales Input'!J85,IF('Consolidated Sales'!$C$2=9,'Sales Input'!K85,IF('Consolidated Sales'!$C$2=10,'Sales Input'!L85,IF('Consolidated Sales'!$C$2=11,'Sales Input'!M85,IF('Consolidated Sales'!$C$2=12,'Sales Input'!N85,IF('Consolidated Sales'!$C$2=13,'Sales Input'!O85,0))))))))))))) -> 0 | D16: =SUM(C16-E16-G16-I16-K16) -> 0 | E16: =IF('Consolidated Sales'!$C$2=1,'Sales Input'!C113,IF('Consolidated Sales'!$C$2=2,'Sales Input'!D113,IF('Consolidated Sales'!$C$2=3,'Sales Input'!E113,IF('Consolidated Sales'!$C$2=4,'Sales Input'!F113,IF('Consolidated Sales'!$C$2=5,'Sales Input'!G113,IF('Consolidated Sales'!$C$2=6,'Sales Input'!H113,IF('Consolidated Sales'!$C$2=7,'Sales Input'!I113,IF('Consolidated Sales'!$C$2=8,'Sales Input'!J113,IF('Consolidated Sales'!$C$2=9,'Sales Input'!K113,IF('Consolidated Sales'!$C$2=10,'Sales Input'!L113,IF('Consolidated Sales'!$C$2=11,'Sales Input'!M113,IF('Consolidated Sales'!$C$2=12,'Sales Input'!N113,IF('Consolidated Sales'!$C$2=13,'Sales Input'!O113,0))))))))))))) -> 0 | F16: =SUM(C16-E16-G16-I16-K16) -> 0 | G16: =IF('Consolidated Sales'!$C$2=1,'Sales Input'!C135,IF('Consolidated Sales'!$C$2=2,'Sales Input'!D135,IF('Consolidated Sales'!$C$2=3,'Sales Input'!E135,IF('Consolidated Sales'!$C$2=4,'Sales Input'!F135,IF('Consolidated Sales'!$C$2=5,'Sales Input'!G135,IF('Consolidated Sales'!$C$2=6,'Sales Input'!H135,IF('Consolidated Sales'!$C$2=7,'Sales Input'!I135,IF('Consolidated Sales'!$C$2=8,'Sales Input'!J135,IF('Consolidated Sales'!$C$2=9,'Sales Input'!K135,IF('Consolidated Sales'!$C$2=10,'Sales Input'!L135,IF('Consolidated Sales'!$C$2=11,'Sales Input'!M135,IF('Consolidated Sales'!$C$2=12,'Sales Input'!N135,IF('Consolidated Sales'!$C$2=13,'Sales Input'!O135,0))))))))))))) -> 0 | H16: =C16-E16-G16-I16-K16 -> 0 | I16: =IF('Consolidated Sales'!$C$2=1,'Sales Input'!C157,IF('Consolidated Sales'!$C$2=2,'Sales Input'!D157,IF('Consolidated Sales'!$C$2=3,'Sales Input'!E157,IF('Consolidated Sales'!$C$2=4,'Sales Input'!F157,IF('Consolidated Sales'!$C$2=5,'Sales Input'!G157,IF('Consolidated Sales'!$C$2=6,'Sales Input'!H157,IF('Consolidated Sales'!$C$2=7,'Sales Input'!I157,IF('Consolidated Sales'!$C$2=8,'Sales Input'!J157,IF('Consolidated Sales'!$C$2=9,'Sales Input'!K157,IF('Consolidated Sales'!$C$2=10,'Sales Input'!L157,IF('Consolidated Sales'!$C$2=11,'Sales Input'!M157,IF('Consolidated Sales'!$C$2=12,'Sales Input'!N157,IF('Consolidated Sales'!$C$2=13,'Sales Input'!O157,0))))))))))))) -> 0 | J16: =C16-E16-G16-I16-K16 -> 0 | K16: =IF('Consolidated Sales'!$C$2=1,'Sales Input'!C179,IF('Consolidated Sales'!$C$2=2,'Sales Input'!D179,IF('Consolidated Sales'!$C$2=3,'Sales Input'!E179,IF('Consolidated Sales'!$C$2=4,'Sales Input'!F179,IF('Consolidated Sales'!$C$2=5,'Sales Input'!G179,IF('Consolidated Sales'!$C$2=6,'Sales Input'!H179,IF('Consolidated Sales'!$C$2=7,'Sales Input'!I179,IF('Consolidated Sales'!$C$2=8,'Sales Input'!J179,IF('Consolidated Sales'!$C$2=9,'Sales Input'!K179,IF('Consolidated Sales'!$C$2=10,'Sales Input'!L179,IF('Consolidated Sales'!$C$2=11,'Sales Input'!M179,IF('Consolidated Sales'!$C$2=12,'Sales Input'!N179,IF('Consolidated Sales'!$C$2=13,'Sales Input'!O179,0))))))))))))) -> 0 | L16: =C16-E16-G16-I16-K16 -> 0
